[2023-01-26T17:15:54.189+0000] {processor.py:153} INFO - Started process (PID=66) to work on /opt/airflow/dags/etlcommands.py
[2023-01-26T17:15:54.190+0000] {processor.py:743} INFO - Processing file /opt/airflow/dags/etlcommands.py for tasks to queue
[2023-01-26T17:15:54.190+0000] {logging_mixin.py:137} INFO - [2023-01-26T17:15:54.190+0000] {dagbag.py:538} INFO - Filling up the DagBag from /opt/airflow/dags/etlcommands.py
[2023-01-26T17:15:58.111+0000] {logging_mixin.py:137} INFO - [2023-01-26T17:15:58.094+0000] {dagbag.py:343} ERROR - Failed to import: /opt/airflow/dags/etlcommands.py
Traceback (most recent call last):
  File "/home/airflow/.local/lib/python3.7/site-packages/airflow/models/dagbag.py", line 339, in parse
    loader.exec_module(new_module)
  File "<frozen importlib._bootstrap_external>", line 728, in exec_module
  File "<frozen importlib._bootstrap>", line 219, in _call_with_frames_removed
  File "/opt/airflow/dags/etlcommands.py", line 46, in <module>
    capture_account_data >> is_valid >> [valid, nvalid]
NameError: name 'nvalid' is not defined
[2023-01-26T17:15:58.112+0000] {processor.py:755} WARNING - No viable dags retrieved from /opt/airflow/dags/etlcommands.py
[2023-01-26T17:15:58.150+0000] {processor.py:175} INFO - Processing /opt/airflow/dags/etlcommands.py took 3.969 seconds
[2023-01-26T17:16:28.400+0000] {processor.py:153} INFO - Started process (PID=146) to work on /opt/airflow/dags/etlcommands.py
[2023-01-26T17:16:28.401+0000] {processor.py:743} INFO - Processing file /opt/airflow/dags/etlcommands.py for tasks to queue
[2023-01-26T17:16:28.402+0000] {logging_mixin.py:137} INFO - [2023-01-26T17:16:28.402+0000] {dagbag.py:538} INFO - Filling up the DagBag from /opt/airflow/dags/etlcommands.py
[2023-01-26T17:16:28.669+0000] {logging_mixin.py:137} INFO - [2023-01-26T17:16:28.668+0000] {dagbag.py:343} ERROR - Failed to import: /opt/airflow/dags/etlcommands.py
Traceback (most recent call last):
  File "/home/airflow/.local/lib/python3.7/site-packages/airflow/models/dagbag.py", line 339, in parse
    loader.exec_module(new_module)
  File "<frozen importlib._bootstrap_external>", line 728, in exec_module
  File "<frozen importlib._bootstrap>", line 219, in _call_with_frames_removed
  File "/opt/airflow/dags/etlcommands.py", line 46, in <module>
    capture_account_data >> is_valid >> [valid, nvalid]
NameError: name 'nvalid' is not defined
[2023-01-26T17:16:28.670+0000] {processor.py:755} WARNING - No viable dags retrieved from /opt/airflow/dags/etlcommands.py
[2023-01-26T17:16:28.693+0000] {processor.py:175} INFO - Processing /opt/airflow/dags/etlcommands.py took 0.297 seconds
[2023-01-26T17:16:58.784+0000] {processor.py:153} INFO - Started process (PID=224) to work on /opt/airflow/dags/etlcommands.py
[2023-01-26T17:16:58.785+0000] {processor.py:743} INFO - Processing file /opt/airflow/dags/etlcommands.py for tasks to queue
[2023-01-26T17:16:58.786+0000] {logging_mixin.py:137} INFO - [2023-01-26T17:16:58.786+0000] {dagbag.py:538} INFO - Filling up the DagBag from /opt/airflow/dags/etlcommands.py
[2023-01-26T17:16:59.151+0000] {logging_mixin.py:137} INFO - [2023-01-26T17:16:59.150+0000] {dagbag.py:343} ERROR - Failed to import: /opt/airflow/dags/etlcommands.py
Traceback (most recent call last):
  File "/home/airflow/.local/lib/python3.7/site-packages/airflow/models/dagbag.py", line 339, in parse
    loader.exec_module(new_module)
  File "<frozen importlib._bootstrap_external>", line 728, in exec_module
  File "<frozen importlib._bootstrap>", line 219, in _call_with_frames_removed
  File "/opt/airflow/dags/etlcommands.py", line 46, in <module>
    capture_account_data >> is_valid >> [valid, nvalid]
NameError: name 'nvalid' is not defined
[2023-01-26T17:16:59.152+0000] {processor.py:755} WARNING - No viable dags retrieved from /opt/airflow/dags/etlcommands.py
[2023-01-26T17:16:59.179+0000] {processor.py:175} INFO - Processing /opt/airflow/dags/etlcommands.py took 0.400 seconds
[2023-01-26T17:17:29.389+0000] {processor.py:153} INFO - Started process (PID=290) to work on /opt/airflow/dags/etlcommands.py
[2023-01-26T17:17:29.390+0000] {processor.py:743} INFO - Processing file /opt/airflow/dags/etlcommands.py for tasks to queue
[2023-01-26T17:17:29.391+0000] {logging_mixin.py:137} INFO - [2023-01-26T17:17:29.391+0000] {dagbag.py:538} INFO - Filling up the DagBag from /opt/airflow/dags/etlcommands.py
[2023-01-26T17:17:29.659+0000] {logging_mixin.py:137} INFO - [2023-01-26T17:17:29.658+0000] {dagbag.py:343} ERROR - Failed to import: /opt/airflow/dags/etlcommands.py
Traceback (most recent call last):
  File "/home/airflow/.local/lib/python3.7/site-packages/airflow/models/dagbag.py", line 339, in parse
    loader.exec_module(new_module)
  File "<frozen importlib._bootstrap_external>", line 728, in exec_module
  File "<frozen importlib._bootstrap>", line 219, in _call_with_frames_removed
  File "/opt/airflow/dags/etlcommands.py", line 46, in <module>
    capture_account_data >> is_valid >> [valid, nvalid]
NameError: name 'nvalid' is not defined
[2023-01-26T17:17:29.659+0000] {processor.py:755} WARNING - No viable dags retrieved from /opt/airflow/dags/etlcommands.py
[2023-01-26T17:17:29.682+0000] {processor.py:175} INFO - Processing /opt/airflow/dags/etlcommands.py took 0.296 seconds
[2023-01-26T17:17:59.892+0000] {processor.py:153} INFO - Started process (PID=358) to work on /opt/airflow/dags/etlcommands.py
[2023-01-26T17:17:59.898+0000] {processor.py:743} INFO - Processing file /opt/airflow/dags/etlcommands.py for tasks to queue
[2023-01-26T17:17:59.899+0000] {logging_mixin.py:137} INFO - [2023-01-26T17:17:59.899+0000] {dagbag.py:538} INFO - Filling up the DagBag from /opt/airflow/dags/etlcommands.py
[2023-01-26T17:18:00.351+0000] {logging_mixin.py:137} INFO - [2023-01-26T17:18:00.348+0000] {dagbag.py:343} ERROR - Failed to import: /opt/airflow/dags/etlcommands.py
Traceback (most recent call last):
  File "/home/airflow/.local/lib/python3.7/site-packages/airflow/models/dagbag.py", line 339, in parse
    loader.exec_module(new_module)
  File "<frozen importlib._bootstrap_external>", line 728, in exec_module
  File "<frozen importlib._bootstrap>", line 219, in _call_with_frames_removed
  File "/opt/airflow/dags/etlcommands.py", line 46, in <module>
    capture_account_data >> is_valid >> [valid, nvalid]
NameError: name 'nvalid' is not defined
[2023-01-26T17:18:00.351+0000] {processor.py:755} WARNING - No viable dags retrieved from /opt/airflow/dags/etlcommands.py
[2023-01-26T17:18:00.384+0000] {processor.py:175} INFO - Processing /opt/airflow/dags/etlcommands.py took 0.497 seconds
[2023-01-26T17:18:30.543+0000] {processor.py:153} INFO - Started process (PID=428) to work on /opt/airflow/dags/etlcommands.py
[2023-01-26T17:18:30.544+0000] {processor.py:743} INFO - Processing file /opt/airflow/dags/etlcommands.py for tasks to queue
[2023-01-26T17:18:30.545+0000] {logging_mixin.py:137} INFO - [2023-01-26T17:18:30.545+0000] {dagbag.py:538} INFO - Filling up the DagBag from /opt/airflow/dags/etlcommands.py
[2023-01-26T17:18:30.846+0000] {logging_mixin.py:137} INFO - [2023-01-26T17:18:30.844+0000] {dagbag.py:343} ERROR - Failed to import: /opt/airflow/dags/etlcommands.py
Traceback (most recent call last):
  File "/home/airflow/.local/lib/python3.7/site-packages/airflow/models/dagbag.py", line 339, in parse
    loader.exec_module(new_module)
  File "<frozen importlib._bootstrap_external>", line 728, in exec_module
  File "<frozen importlib._bootstrap>", line 219, in _call_with_frames_removed
  File "/opt/airflow/dags/etlcommands.py", line 46, in <module>
    capture_account_data >> is_valid >> [valid, nvalid]
NameError: name 'nvalid' is not defined
[2023-01-26T17:18:30.846+0000] {processor.py:755} WARNING - No viable dags retrieved from /opt/airflow/dags/etlcommands.py
[2023-01-26T17:18:30.874+0000] {processor.py:175} INFO - Processing /opt/airflow/dags/etlcommands.py took 0.337 seconds
[2023-01-26T17:19:01.468+0000] {processor.py:153} INFO - Started process (PID=502) to work on /opt/airflow/dags/etlcommands.py
[2023-01-26T17:19:01.469+0000] {processor.py:743} INFO - Processing file /opt/airflow/dags/etlcommands.py for tasks to queue
[2023-01-26T17:19:01.470+0000] {logging_mixin.py:137} INFO - [2023-01-26T17:19:01.470+0000] {dagbag.py:538} INFO - Filling up the DagBag from /opt/airflow/dags/etlcommands.py
[2023-01-26T17:19:01.818+0000] {logging_mixin.py:137} INFO - [2023-01-26T17:19:01.817+0000] {dagbag.py:343} ERROR - Failed to import: /opt/airflow/dags/etlcommands.py
Traceback (most recent call last):
  File "/home/airflow/.local/lib/python3.7/site-packages/airflow/models/dagbag.py", line 339, in parse
    loader.exec_module(new_module)
  File "<frozen importlib._bootstrap_external>", line 728, in exec_module
  File "<frozen importlib._bootstrap>", line 219, in _call_with_frames_removed
  File "/opt/airflow/dags/etlcommands.py", line 46, in <module>
    capture_account_data >> is_valid >> [valid, nvalid]
NameError: name 'nvalid' is not defined
[2023-01-26T17:19:01.818+0000] {processor.py:755} WARNING - No viable dags retrieved from /opt/airflow/dags/etlcommands.py
[2023-01-26T17:19:01.841+0000] {processor.py:175} INFO - Processing /opt/airflow/dags/etlcommands.py took 0.377 seconds
[2023-01-26T17:19:31.911+0000] {processor.py:153} INFO - Started process (PID=571) to work on /opt/airflow/dags/etlcommands.py
[2023-01-26T17:19:31.912+0000] {processor.py:743} INFO - Processing file /opt/airflow/dags/etlcommands.py for tasks to queue
[2023-01-26T17:19:31.912+0000] {logging_mixin.py:137} INFO - [2023-01-26T17:19:31.912+0000] {dagbag.py:538} INFO - Filling up the DagBag from /opt/airflow/dags/etlcommands.py
[2023-01-26T17:19:32.177+0000] {logging_mixin.py:137} INFO - [2023-01-26T17:19:32.175+0000] {dagbag.py:343} ERROR - Failed to import: /opt/airflow/dags/etlcommands.py
Traceback (most recent call last):
  File "/home/airflow/.local/lib/python3.7/site-packages/airflow/models/dagbag.py", line 339, in parse
    loader.exec_module(new_module)
  File "<frozen importlib._bootstrap_external>", line 728, in exec_module
  File "<frozen importlib._bootstrap>", line 219, in _call_with_frames_removed
  File "/opt/airflow/dags/etlcommands.py", line 46, in <module>
    capture_account_data >> is_valid >> [valid, nvalid]
NameError: name 'nvalid' is not defined
[2023-01-26T17:19:32.177+0000] {processor.py:755} WARNING - No viable dags retrieved from /opt/airflow/dags/etlcommands.py
[2023-01-26T17:19:32.203+0000] {processor.py:175} INFO - Processing /opt/airflow/dags/etlcommands.py took 0.295 seconds
[2023-01-26T17:20:02.306+0000] {processor.py:153} INFO - Started process (PID=638) to work on /opt/airflow/dags/etlcommands.py
[2023-01-26T17:20:02.308+0000] {processor.py:743} INFO - Processing file /opt/airflow/dags/etlcommands.py for tasks to queue
[2023-01-26T17:20:02.309+0000] {logging_mixin.py:137} INFO - [2023-01-26T17:20:02.308+0000] {dagbag.py:538} INFO - Filling up the DagBag from /opt/airflow/dags/etlcommands.py
[2023-01-26T17:20:02.564+0000] {logging_mixin.py:137} INFO - [2023-01-26T17:20:02.563+0000] {dagbag.py:343} ERROR - Failed to import: /opt/airflow/dags/etlcommands.py
Traceback (most recent call last):
  File "/home/airflow/.local/lib/python3.7/site-packages/airflow/models/dagbag.py", line 339, in parse
    loader.exec_module(new_module)
  File "<frozen importlib._bootstrap_external>", line 728, in exec_module
  File "<frozen importlib._bootstrap>", line 219, in _call_with_frames_removed
  File "/opt/airflow/dags/etlcommands.py", line 46, in <module>
    capture_account_data >> is_valid >> [valid, nvalid]
NameError: name 'nvalid' is not defined
[2023-01-26T17:20:02.565+0000] {processor.py:755} WARNING - No viable dags retrieved from /opt/airflow/dags/etlcommands.py
[2023-01-26T17:20:02.592+0000] {processor.py:175} INFO - Processing /opt/airflow/dags/etlcommands.py took 0.292 seconds
[2023-01-26T17:20:33.469+0000] {processor.py:153} INFO - Started process (PID=715) to work on /opt/airflow/dags/etlcommands.py
[2023-01-26T17:20:33.470+0000] {processor.py:743} INFO - Processing file /opt/airflow/dags/etlcommands.py for tasks to queue
[2023-01-26T17:20:33.470+0000] {logging_mixin.py:137} INFO - [2023-01-26T17:20:33.470+0000] {dagbag.py:538} INFO - Filling up the DagBag from /opt/airflow/dags/etlcommands.py
[2023-01-26T17:20:33.717+0000] {logging_mixin.py:137} INFO - [2023-01-26T17:20:33.716+0000] {dagbag.py:343} ERROR - Failed to import: /opt/airflow/dags/etlcommands.py
Traceback (most recent call last):
  File "/home/airflow/.local/lib/python3.7/site-packages/airflow/models/dagbag.py", line 339, in parse
    loader.exec_module(new_module)
  File "<frozen importlib._bootstrap_external>", line 728, in exec_module
  File "<frozen importlib._bootstrap>", line 219, in _call_with_frames_removed
  File "/opt/airflow/dags/etlcommands.py", line 46, in <module>
    capture_account_data >> is_valid >> [valid, nvalid]
NameError: name 'nvalid' is not defined
[2023-01-26T17:20:33.717+0000] {processor.py:755} WARNING - No viable dags retrieved from /opt/airflow/dags/etlcommands.py
[2023-01-26T17:20:33.743+0000] {processor.py:175} INFO - Processing /opt/airflow/dags/etlcommands.py took 0.278 seconds
[2023-01-26T17:21:04.219+0000] {processor.py:153} INFO - Started process (PID=789) to work on /opt/airflow/dags/etlcommands.py
[2023-01-26T17:21:04.220+0000] {processor.py:743} INFO - Processing file /opt/airflow/dags/etlcommands.py for tasks to queue
[2023-01-26T17:21:04.221+0000] {logging_mixin.py:137} INFO - [2023-01-26T17:21:04.221+0000] {dagbag.py:538} INFO - Filling up the DagBag from /opt/airflow/dags/etlcommands.py
[2023-01-26T17:21:04.519+0000] {logging_mixin.py:137} INFO - [2023-01-26T17:21:04.518+0000] {dagbag.py:343} ERROR - Failed to import: /opt/airflow/dags/etlcommands.py
Traceback (most recent call last):
  File "/home/airflow/.local/lib/python3.7/site-packages/airflow/models/dagbag.py", line 339, in parse
    loader.exec_module(new_module)
  File "<frozen importlib._bootstrap_external>", line 728, in exec_module
  File "<frozen importlib._bootstrap>", line 219, in _call_with_frames_removed
  File "/opt/airflow/dags/etlcommands.py", line 46, in <module>
    capture_account_data >> is_valid >> [valid, nvalid]
NameError: name 'nvalid' is not defined
[2023-01-26T17:21:04.520+0000] {processor.py:755} WARNING - No viable dags retrieved from /opt/airflow/dags/etlcommands.py
[2023-01-26T17:21:04.545+0000] {processor.py:175} INFO - Processing /opt/airflow/dags/etlcommands.py took 0.331 seconds
[2023-01-26T17:21:34.872+0000] {processor.py:153} INFO - Started process (PID=857) to work on /opt/airflow/dags/etlcommands.py
[2023-01-26T17:21:34.873+0000] {processor.py:743} INFO - Processing file /opt/airflow/dags/etlcommands.py for tasks to queue
[2023-01-26T17:21:34.874+0000] {logging_mixin.py:137} INFO - [2023-01-26T17:21:34.874+0000] {dagbag.py:538} INFO - Filling up the DagBag from /opt/airflow/dags/etlcommands.py
[2023-01-26T17:21:35.111+0000] {logging_mixin.py:137} INFO - [2023-01-26T17:21:35.111+0000] {dagbag.py:343} ERROR - Failed to import: /opt/airflow/dags/etlcommands.py
Traceback (most recent call last):
  File "/home/airflow/.local/lib/python3.7/site-packages/airflow/models/dagbag.py", line 339, in parse
    loader.exec_module(new_module)
  File "<frozen importlib._bootstrap_external>", line 728, in exec_module
  File "<frozen importlib._bootstrap>", line 219, in _call_with_frames_removed
  File "/opt/airflow/dags/etlcommands.py", line 46, in <module>
    capture_account_data >> is_valid >> [valid, nvalid]
NameError: name 'nvalid' is not defined
[2023-01-26T17:21:35.112+0000] {processor.py:755} WARNING - No viable dags retrieved from /opt/airflow/dags/etlcommands.py
[2023-01-26T17:21:35.143+0000] {processor.py:175} INFO - Processing /opt/airflow/dags/etlcommands.py took 0.274 seconds
[2023-01-26T17:22:05.800+0000] {processor.py:153} INFO - Started process (PID=922) to work on /opt/airflow/dags/etlcommands.py
[2023-01-26T17:22:05.801+0000] {processor.py:743} INFO - Processing file /opt/airflow/dags/etlcommands.py for tasks to queue
[2023-01-26T17:22:05.801+0000] {logging_mixin.py:137} INFO - [2023-01-26T17:22:05.801+0000] {dagbag.py:538} INFO - Filling up the DagBag from /opt/airflow/dags/etlcommands.py
[2023-01-26T17:22:06.144+0000] {logging_mixin.py:137} INFO - [2023-01-26T17:22:06.143+0000] {dagbag.py:343} ERROR - Failed to import: /opt/airflow/dags/etlcommands.py
Traceback (most recent call last):
  File "/home/airflow/.local/lib/python3.7/site-packages/airflow/models/dagbag.py", line 339, in parse
    loader.exec_module(new_module)
  File "<frozen importlib._bootstrap_external>", line 728, in exec_module
  File "<frozen importlib._bootstrap>", line 219, in _call_with_frames_removed
  File "/opt/airflow/dags/etlcommands.py", line 46, in <module>
    capture_account_data >> is_valid >> [valid, nvalid]
NameError: name 'nvalid' is not defined
[2023-01-26T17:22:06.147+0000] {processor.py:755} WARNING - No viable dags retrieved from /opt/airflow/dags/etlcommands.py
[2023-01-26T17:22:06.188+0000] {processor.py:175} INFO - Processing /opt/airflow/dags/etlcommands.py took 0.393 seconds
[2023-01-26T17:22:36.299+0000] {processor.py:153} INFO - Started process (PID=999) to work on /opt/airflow/dags/etlcommands.py
[2023-01-26T17:22:36.300+0000] {processor.py:743} INFO - Processing file /opt/airflow/dags/etlcommands.py for tasks to queue
[2023-01-26T17:22:36.300+0000] {logging_mixin.py:137} INFO - [2023-01-26T17:22:36.300+0000] {dagbag.py:538} INFO - Filling up the DagBag from /opt/airflow/dags/etlcommands.py
[2023-01-26T17:22:36.549+0000] {logging_mixin.py:137} INFO - [2023-01-26T17:22:36.548+0000] {dagbag.py:343} ERROR - Failed to import: /opt/airflow/dags/etlcommands.py
Traceback (most recent call last):
  File "/home/airflow/.local/lib/python3.7/site-packages/airflow/models/dagbag.py", line 339, in parse
    loader.exec_module(new_module)
  File "<frozen importlib._bootstrap_external>", line 728, in exec_module
  File "<frozen importlib._bootstrap>", line 219, in _call_with_frames_removed
  File "/opt/airflow/dags/etlcommands.py", line 46, in <module>
    capture_account_data >> is_valid >> [valid, nvalid]
NameError: name 'nvalid' is not defined
[2023-01-26T17:22:36.550+0000] {processor.py:755} WARNING - No viable dags retrieved from /opt/airflow/dags/etlcommands.py
[2023-01-26T17:22:36.572+0000] {processor.py:175} INFO - Processing /opt/airflow/dags/etlcommands.py took 0.277 seconds
[2023-01-26T17:23:07.169+0000] {processor.py:153} INFO - Started process (PID=1064) to work on /opt/airflow/dags/etlcommands.py
[2023-01-26T17:23:07.171+0000] {processor.py:743} INFO - Processing file /opt/airflow/dags/etlcommands.py for tasks to queue
[2023-01-26T17:23:07.172+0000] {logging_mixin.py:137} INFO - [2023-01-26T17:23:07.172+0000] {dagbag.py:538} INFO - Filling up the DagBag from /opt/airflow/dags/etlcommands.py
[2023-01-26T17:23:07.478+0000] {logging_mixin.py:137} INFO - [2023-01-26T17:23:07.478+0000] {dagbag.py:343} ERROR - Failed to import: /opt/airflow/dags/etlcommands.py
Traceback (most recent call last):
  File "/home/airflow/.local/lib/python3.7/site-packages/airflow/models/dagbag.py", line 339, in parse
    loader.exec_module(new_module)
  File "<frozen importlib._bootstrap_external>", line 728, in exec_module
  File "<frozen importlib._bootstrap>", line 219, in _call_with_frames_removed
  File "/opt/airflow/dags/etlcommands.py", line 46, in <module>
    capture_account_data >> is_valid >> [valid, nvalid]
NameError: name 'nvalid' is not defined
[2023-01-26T17:23:07.479+0000] {processor.py:755} WARNING - No viable dags retrieved from /opt/airflow/dags/etlcommands.py
[2023-01-26T17:23:07.507+0000] {processor.py:175} INFO - Processing /opt/airflow/dags/etlcommands.py took 0.342 seconds
[2023-01-26T17:23:38.426+0000] {processor.py:153} INFO - Started process (PID=1142) to work on /opt/airflow/dags/etlcommands.py
[2023-01-26T17:23:38.427+0000] {processor.py:743} INFO - Processing file /opt/airflow/dags/etlcommands.py for tasks to queue
[2023-01-26T17:23:38.427+0000] {logging_mixin.py:137} INFO - [2023-01-26T17:23:38.427+0000] {dagbag.py:538} INFO - Filling up the DagBag from /opt/airflow/dags/etlcommands.py
[2023-01-26T17:23:38.680+0000] {logging_mixin.py:137} INFO - [2023-01-26T17:23:38.680+0000] {dagbag.py:343} ERROR - Failed to import: /opt/airflow/dags/etlcommands.py
Traceback (most recent call last):
  File "/home/airflow/.local/lib/python3.7/site-packages/airflow/models/dagbag.py", line 339, in parse
    loader.exec_module(new_module)
  File "<frozen importlib._bootstrap_external>", line 728, in exec_module
  File "<frozen importlib._bootstrap>", line 219, in _call_with_frames_removed
  File "/opt/airflow/dags/etlcommands.py", line 46, in <module>
    capture_account_data >> is_valid >> [valid, nvalid]
NameError: name 'nvalid' is not defined
[2023-01-26T17:23:38.681+0000] {processor.py:755} WARNING - No viable dags retrieved from /opt/airflow/dags/etlcommands.py
[2023-01-26T17:23:38.703+0000] {processor.py:175} INFO - Processing /opt/airflow/dags/etlcommands.py took 0.281 seconds
[2023-01-26T17:24:09.432+0000] {processor.py:153} INFO - Started process (PID=1216) to work on /opt/airflow/dags/etlcommands.py
[2023-01-26T17:24:09.433+0000] {processor.py:743} INFO - Processing file /opt/airflow/dags/etlcommands.py for tasks to queue
[2023-01-26T17:24:09.434+0000] {logging_mixin.py:137} INFO - [2023-01-26T17:24:09.434+0000] {dagbag.py:538} INFO - Filling up the DagBag from /opt/airflow/dags/etlcommands.py
[2023-01-26T17:24:09.722+0000] {logging_mixin.py:137} INFO - [2023-01-26T17:24:09.720+0000] {dagbag.py:343} ERROR - Failed to import: /opt/airflow/dags/etlcommands.py
Traceback (most recent call last):
  File "/home/airflow/.local/lib/python3.7/site-packages/airflow/models/dagbag.py", line 339, in parse
    loader.exec_module(new_module)
  File "<frozen importlib._bootstrap_external>", line 728, in exec_module
  File "<frozen importlib._bootstrap>", line 219, in _call_with_frames_removed
  File "/opt/airflow/dags/etlcommands.py", line 46, in <module>
    capture_account_data >> is_valid >> [valid, nvalid]
NameError: name 'nvalid' is not defined
[2023-01-26T17:24:09.722+0000] {processor.py:755} WARNING - No viable dags retrieved from /opt/airflow/dags/etlcommands.py
[2023-01-26T17:24:09.770+0000] {processor.py:175} INFO - Processing /opt/airflow/dags/etlcommands.py took 0.342 seconds
[2023-01-26T17:24:40.374+0000] {processor.py:153} INFO - Started process (PID=1284) to work on /opt/airflow/dags/etlcommands.py
[2023-01-26T17:24:40.375+0000] {processor.py:743} INFO - Processing file /opt/airflow/dags/etlcommands.py for tasks to queue
[2023-01-26T17:24:40.376+0000] {logging_mixin.py:137} INFO - [2023-01-26T17:24:40.376+0000] {dagbag.py:538} INFO - Filling up the DagBag from /opt/airflow/dags/etlcommands.py
[2023-01-26T17:24:40.651+0000] {logging_mixin.py:137} INFO - [2023-01-26T17:24:40.649+0000] {dagbag.py:343} ERROR - Failed to import: /opt/airflow/dags/etlcommands.py
Traceback (most recent call last):
  File "/home/airflow/.local/lib/python3.7/site-packages/airflow/models/dagbag.py", line 339, in parse
    loader.exec_module(new_module)
  File "<frozen importlib._bootstrap_external>", line 728, in exec_module
  File "<frozen importlib._bootstrap>", line 219, in _call_with_frames_removed
  File "/opt/airflow/dags/etlcommands.py", line 46, in <module>
    capture_account_data >> is_valid >> [valid, nvalid]
NameError: name 'nvalid' is not defined
[2023-01-26T17:24:40.651+0000] {processor.py:755} WARNING - No viable dags retrieved from /opt/airflow/dags/etlcommands.py
[2023-01-26T17:24:40.679+0000] {processor.py:175} INFO - Processing /opt/airflow/dags/etlcommands.py took 0.310 seconds
[2023-01-26T17:25:10.762+0000] {processor.py:153} INFO - Started process (PID=1362) to work on /opt/airflow/dags/etlcommands.py
[2023-01-26T17:25:10.763+0000] {processor.py:743} INFO - Processing file /opt/airflow/dags/etlcommands.py for tasks to queue
[2023-01-26T17:25:10.764+0000] {logging_mixin.py:137} INFO - [2023-01-26T17:25:10.764+0000] {dagbag.py:538} INFO - Filling up the DagBag from /opt/airflow/dags/etlcommands.py
[2023-01-26T17:25:11.036+0000] {logging_mixin.py:137} INFO - [2023-01-26T17:25:11.034+0000] {dagbag.py:343} ERROR - Failed to import: /opt/airflow/dags/etlcommands.py
Traceback (most recent call last):
  File "/home/airflow/.local/lib/python3.7/site-packages/airflow/models/dagbag.py", line 339, in parse
    loader.exec_module(new_module)
  File "<frozen importlib._bootstrap_external>", line 728, in exec_module
  File "<frozen importlib._bootstrap>", line 219, in _call_with_frames_removed
  File "/opt/airflow/dags/etlcommands.py", line 46, in <module>
    capture_account_data >> is_valid >> [valid, nvalid]
NameError: name 'nvalid' is not defined
[2023-01-26T17:25:11.036+0000] {processor.py:755} WARNING - No viable dags retrieved from /opt/airflow/dags/etlcommands.py
[2023-01-26T17:25:11.070+0000] {processor.py:175} INFO - Processing /opt/airflow/dags/etlcommands.py took 0.311 seconds
[2023-01-26T17:25:41.466+0000] {processor.py:153} INFO - Started process (PID=1426) to work on /opt/airflow/dags/etlcommands.py
[2023-01-26T17:25:41.467+0000] {processor.py:743} INFO - Processing file /opt/airflow/dags/etlcommands.py for tasks to queue
[2023-01-26T17:25:41.468+0000] {logging_mixin.py:137} INFO - [2023-01-26T17:25:41.468+0000] {dagbag.py:538} INFO - Filling up the DagBag from /opt/airflow/dags/etlcommands.py
[2023-01-26T17:25:41.828+0000] {logging_mixin.py:137} INFO - [2023-01-26T17:25:41.827+0000] {dagbag.py:343} ERROR - Failed to import: /opt/airflow/dags/etlcommands.py
Traceback (most recent call last):
  File "/home/airflow/.local/lib/python3.7/site-packages/airflow/models/dagbag.py", line 339, in parse
    loader.exec_module(new_module)
  File "<frozen importlib._bootstrap_external>", line 728, in exec_module
  File "<frozen importlib._bootstrap>", line 219, in _call_with_frames_removed
  File "/opt/airflow/dags/etlcommands.py", line 46, in <module>
    capture_account_data >> is_valid >> [valid, nvalid]
NameError: name 'nvalid' is not defined
[2023-01-26T17:25:41.829+0000] {processor.py:755} WARNING - No viable dags retrieved from /opt/airflow/dags/etlcommands.py
[2023-01-26T17:25:41.859+0000] {processor.py:175} INFO - Processing /opt/airflow/dags/etlcommands.py took 0.398 seconds
[2023-01-26T17:26:12.119+0000] {processor.py:153} INFO - Started process (PID=1503) to work on /opt/airflow/dags/etlcommands.py
[2023-01-26T17:26:12.121+0000] {processor.py:743} INFO - Processing file /opt/airflow/dags/etlcommands.py for tasks to queue
[2023-01-26T17:26:12.121+0000] {logging_mixin.py:137} INFO - [2023-01-26T17:26:12.121+0000] {dagbag.py:538} INFO - Filling up the DagBag from /opt/airflow/dags/etlcommands.py
[2023-01-26T17:26:12.396+0000] {logging_mixin.py:137} INFO - [2023-01-26T17:26:12.395+0000] {dagbag.py:343} ERROR - Failed to import: /opt/airflow/dags/etlcommands.py
Traceback (most recent call last):
  File "/home/airflow/.local/lib/python3.7/site-packages/airflow/models/dagbag.py", line 339, in parse
    loader.exec_module(new_module)
  File "<frozen importlib._bootstrap_external>", line 728, in exec_module
  File "<frozen importlib._bootstrap>", line 219, in _call_with_frames_removed
  File "/opt/airflow/dags/etlcommands.py", line 46, in <module>
    capture_account_data >> is_valid >> [valid, nvalid]
NameError: name 'nvalid' is not defined
[2023-01-26T17:26:12.396+0000] {processor.py:755} WARNING - No viable dags retrieved from /opt/airflow/dags/etlcommands.py
[2023-01-26T17:26:12.431+0000] {processor.py:175} INFO - Processing /opt/airflow/dags/etlcommands.py took 0.316 seconds
[2023-01-26T17:26:42.932+0000] {processor.py:153} INFO - Started process (PID=1568) to work on /opt/airflow/dags/etlcommands.py
[2023-01-26T17:26:42.933+0000] {processor.py:743} INFO - Processing file /opt/airflow/dags/etlcommands.py for tasks to queue
[2023-01-26T17:26:42.934+0000] {logging_mixin.py:137} INFO - [2023-01-26T17:26:42.934+0000] {dagbag.py:538} INFO - Filling up the DagBag from /opt/airflow/dags/etlcommands.py
[2023-01-26T17:26:43.241+0000] {logging_mixin.py:137} INFO - [2023-01-26T17:26:43.240+0000] {dagbag.py:343} ERROR - Failed to import: /opt/airflow/dags/etlcommands.py
Traceback (most recent call last):
  File "/home/airflow/.local/lib/python3.7/site-packages/airflow/models/dagbag.py", line 339, in parse
    loader.exec_module(new_module)
  File "<frozen importlib._bootstrap_external>", line 728, in exec_module
  File "<frozen importlib._bootstrap>", line 219, in _call_with_frames_removed
  File "/opt/airflow/dags/etlcommands.py", line 46, in <module>
    capture_account_data >> is_valid >> [valid, nvalid]
NameError: name 'nvalid' is not defined
[2023-01-26T17:26:43.242+0000] {processor.py:755} WARNING - No viable dags retrieved from /opt/airflow/dags/etlcommands.py
[2023-01-26T17:26:43.274+0000] {processor.py:175} INFO - Processing /opt/airflow/dags/etlcommands.py took 0.346 seconds
[2023-01-26T17:27:13.535+0000] {processor.py:153} INFO - Started process (PID=1646) to work on /opt/airflow/dags/etlcommands.py
[2023-01-26T17:27:13.536+0000] {processor.py:743} INFO - Processing file /opt/airflow/dags/etlcommands.py for tasks to queue
[2023-01-26T17:27:13.537+0000] {logging_mixin.py:137} INFO - [2023-01-26T17:27:13.537+0000] {dagbag.py:538} INFO - Filling up the DagBag from /opt/airflow/dags/etlcommands.py
[2023-01-26T17:27:13.762+0000] {logging_mixin.py:137} INFO - [2023-01-26T17:27:13.761+0000] {dagbag.py:343} ERROR - Failed to import: /opt/airflow/dags/etlcommands.py
Traceback (most recent call last):
  File "/home/airflow/.local/lib/python3.7/site-packages/airflow/models/dagbag.py", line 339, in parse
    loader.exec_module(new_module)
  File "<frozen importlib._bootstrap_external>", line 728, in exec_module
  File "<frozen importlib._bootstrap>", line 219, in _call_with_frames_removed
  File "/opt/airflow/dags/etlcommands.py", line 46, in <module>
    capture_account_data >> is_valid >> [valid, nvalid]
NameError: name 'nvalid' is not defined
[2023-01-26T17:27:13.763+0000] {processor.py:755} WARNING - No viable dags retrieved from /opt/airflow/dags/etlcommands.py
[2023-01-26T17:27:13.786+0000] {processor.py:175} INFO - Processing /opt/airflow/dags/etlcommands.py took 0.254 seconds
[2023-01-26T17:27:44.531+0000] {processor.py:153} INFO - Started process (PID=1711) to work on /opt/airflow/dags/etlcommands.py
[2023-01-26T17:27:44.534+0000] {processor.py:743} INFO - Processing file /opt/airflow/dags/etlcommands.py for tasks to queue
[2023-01-26T17:27:44.535+0000] {logging_mixin.py:137} INFO - [2023-01-26T17:27:44.535+0000] {dagbag.py:538} INFO - Filling up the DagBag from /opt/airflow/dags/etlcommands.py
[2023-01-26T17:27:44.809+0000] {logging_mixin.py:137} INFO - [2023-01-26T17:27:44.808+0000] {dagbag.py:343} ERROR - Failed to import: /opt/airflow/dags/etlcommands.py
Traceback (most recent call last):
  File "/home/airflow/.local/lib/python3.7/site-packages/airflow/models/dagbag.py", line 339, in parse
    loader.exec_module(new_module)
  File "<frozen importlib._bootstrap_external>", line 728, in exec_module
  File "<frozen importlib._bootstrap>", line 219, in _call_with_frames_removed
  File "/opt/airflow/dags/etlcommands.py", line 46, in <module>
    capture_account_data >> is_valid >> [valid, nvalid]
NameError: name 'nvalid' is not defined
[2023-01-26T17:27:44.810+0000] {processor.py:755} WARNING - No viable dags retrieved from /opt/airflow/dags/etlcommands.py
[2023-01-26T17:27:44.840+0000] {processor.py:175} INFO - Processing /opt/airflow/dags/etlcommands.py took 0.314 seconds
[2023-01-26T17:28:14.875+0000] {processor.py:153} INFO - Started process (PID=1789) to work on /opt/airflow/dags/etlcommands.py
[2023-01-26T17:28:14.876+0000] {processor.py:743} INFO - Processing file /opt/airflow/dags/etlcommands.py for tasks to queue
[2023-01-26T17:28:14.877+0000] {logging_mixin.py:137} INFO - [2023-01-26T17:28:14.877+0000] {dagbag.py:538} INFO - Filling up the DagBag from /opt/airflow/dags/etlcommands.py
[2023-01-26T17:28:15.101+0000] {logging_mixin.py:137} INFO - [2023-01-26T17:28:15.100+0000] {dagbag.py:343} ERROR - Failed to import: /opt/airflow/dags/etlcommands.py
Traceback (most recent call last):
  File "/home/airflow/.local/lib/python3.7/site-packages/airflow/models/dagbag.py", line 339, in parse
    loader.exec_module(new_module)
  File "<frozen importlib._bootstrap_external>", line 728, in exec_module
  File "<frozen importlib._bootstrap>", line 219, in _call_with_frames_removed
  File "/opt/airflow/dags/etlcommands.py", line 46, in <module>
    capture_account_data >> is_valid >> [valid, nvalid]
NameError: name 'nvalid' is not defined
[2023-01-26T17:28:15.101+0000] {processor.py:755} WARNING - No viable dags retrieved from /opt/airflow/dags/etlcommands.py
[2023-01-26T17:28:15.123+0000] {processor.py:175} INFO - Processing /opt/airflow/dags/etlcommands.py took 0.253 seconds
[2023-01-26T17:28:45.143+0000] {processor.py:153} INFO - Started process (PID=1856) to work on /opt/airflow/dags/etlcommands.py
[2023-01-26T17:28:45.144+0000] {processor.py:743} INFO - Processing file /opt/airflow/dags/etlcommands.py for tasks to queue
[2023-01-26T17:28:45.144+0000] {logging_mixin.py:137} INFO - [2023-01-26T17:28:45.144+0000] {dagbag.py:538} INFO - Filling up the DagBag from /opt/airflow/dags/etlcommands.py
[2023-01-26T17:28:45.358+0000] {logging_mixin.py:137} INFO - [2023-01-26T17:28:45.357+0000] {dagbag.py:343} ERROR - Failed to import: /opt/airflow/dags/etlcommands.py
Traceback (most recent call last):
  File "/home/airflow/.local/lib/python3.7/site-packages/airflow/models/dagbag.py", line 339, in parse
    loader.exec_module(new_module)
  File "<frozen importlib._bootstrap_external>", line 728, in exec_module
  File "<frozen importlib._bootstrap>", line 219, in _call_with_frames_removed
  File "/opt/airflow/dags/etlcommands.py", line 46, in <module>
    capture_account_data >> is_valid >> [valid, nvalid]
NameError: name 'nvalid' is not defined
[2023-01-26T17:28:45.358+0000] {processor.py:755} WARNING - No viable dags retrieved from /opt/airflow/dags/etlcommands.py
[2023-01-26T17:28:45.383+0000] {processor.py:175} INFO - Processing /opt/airflow/dags/etlcommands.py took 0.243 seconds
[2023-01-26T17:29:15.446+0000] {processor.py:153} INFO - Started process (PID=1933) to work on /opt/airflow/dags/etlcommands.py
[2023-01-26T17:29:15.447+0000] {processor.py:743} INFO - Processing file /opt/airflow/dags/etlcommands.py for tasks to queue
[2023-01-26T17:29:15.447+0000] {logging_mixin.py:137} INFO - [2023-01-26T17:29:15.447+0000] {dagbag.py:538} INFO - Filling up the DagBag from /opt/airflow/dags/etlcommands.py
[2023-01-26T17:29:15.666+0000] {logging_mixin.py:137} INFO - [2023-01-26T17:29:15.665+0000] {dagbag.py:343} ERROR - Failed to import: /opt/airflow/dags/etlcommands.py
Traceback (most recent call last):
  File "/home/airflow/.local/lib/python3.7/site-packages/airflow/models/dagbag.py", line 339, in parse
    loader.exec_module(new_module)
  File "<frozen importlib._bootstrap_external>", line 728, in exec_module
  File "<frozen importlib._bootstrap>", line 219, in _call_with_frames_removed
  File "/opt/airflow/dags/etlcommands.py", line 46, in <module>
    capture_account_data >> is_valid >> [valid, nvalid]
NameError: name 'nvalid' is not defined
[2023-01-26T17:29:15.666+0000] {processor.py:755} WARNING - No viable dags retrieved from /opt/airflow/dags/etlcommands.py
[2023-01-26T17:29:15.689+0000] {processor.py:175} INFO - Processing /opt/airflow/dags/etlcommands.py took 0.246 seconds
[2023-01-26T17:29:46.013+0000] {processor.py:153} INFO - Started process (PID=1996) to work on /opt/airflow/dags/etlcommands.py
[2023-01-26T17:29:46.021+0000] {processor.py:743} INFO - Processing file /opt/airflow/dags/etlcommands.py for tasks to queue
[2023-01-26T17:29:46.021+0000] {logging_mixin.py:137} INFO - [2023-01-26T17:29:46.021+0000] {dagbag.py:538} INFO - Filling up the DagBag from /opt/airflow/dags/etlcommands.py
[2023-01-26T17:29:46.253+0000] {logging_mixin.py:137} INFO - [2023-01-26T17:29:46.252+0000] {dagbag.py:343} ERROR - Failed to import: /opt/airflow/dags/etlcommands.py
Traceback (most recent call last):
  File "/home/airflow/.local/lib/python3.7/site-packages/airflow/models/dagbag.py", line 339, in parse
    loader.exec_module(new_module)
  File "<frozen importlib._bootstrap_external>", line 728, in exec_module
  File "<frozen importlib._bootstrap>", line 219, in _call_with_frames_removed
  File "/opt/airflow/dags/etlcommands.py", line 46, in <module>
    capture_account_data >> is_valid >> [valid, nvalid]
NameError: name 'nvalid' is not defined
[2023-01-26T17:29:46.253+0000] {processor.py:755} WARNING - No viable dags retrieved from /opt/airflow/dags/etlcommands.py
[2023-01-26T17:29:46.276+0000] {processor.py:175} INFO - Processing /opt/airflow/dags/etlcommands.py took 0.267 seconds
[2023-01-26T17:30:16.845+0000] {processor.py:153} INFO - Started process (PID=2074) to work on /opt/airflow/dags/etlcommands.py
[2023-01-26T17:30:16.846+0000] {processor.py:743} INFO - Processing file /opt/airflow/dags/etlcommands.py for tasks to queue
[2023-01-26T17:30:16.847+0000] {logging_mixin.py:137} INFO - [2023-01-26T17:30:16.847+0000] {dagbag.py:538} INFO - Filling up the DagBag from /opt/airflow/dags/etlcommands.py
[2023-01-26T17:30:17.071+0000] {logging_mixin.py:137} INFO - [2023-01-26T17:30:17.070+0000] {dagbag.py:343} ERROR - Failed to import: /opt/airflow/dags/etlcommands.py
Traceback (most recent call last):
  File "/home/airflow/.local/lib/python3.7/site-packages/airflow/models/dagbag.py", line 339, in parse
    loader.exec_module(new_module)
  File "<frozen importlib._bootstrap_external>", line 728, in exec_module
  File "<frozen importlib._bootstrap>", line 219, in _call_with_frames_removed
  File "/opt/airflow/dags/etlcommands.py", line 46, in <module>
    capture_account_data >> is_valid >> [valid, nvalid]
NameError: name 'nvalid' is not defined
[2023-01-26T17:30:17.071+0000] {processor.py:755} WARNING - No viable dags retrieved from /opt/airflow/dags/etlcommands.py
[2023-01-26T17:30:17.094+0000] {processor.py:175} INFO - Processing /opt/airflow/dags/etlcommands.py took 0.253 seconds
[2023-01-26T17:30:47.535+0000] {processor.py:153} INFO - Started process (PID=2139) to work on /opt/airflow/dags/etlcommands.py
[2023-01-26T17:30:47.536+0000] {processor.py:743} INFO - Processing file /opt/airflow/dags/etlcommands.py for tasks to queue
[2023-01-26T17:30:47.537+0000] {logging_mixin.py:137} INFO - [2023-01-26T17:30:47.536+0000] {dagbag.py:538} INFO - Filling up the DagBag from /opt/airflow/dags/etlcommands.py
[2023-01-26T17:30:47.771+0000] {logging_mixin.py:137} INFO - [2023-01-26T17:30:47.770+0000] {dagbag.py:343} ERROR - Failed to import: /opt/airflow/dags/etlcommands.py
Traceback (most recent call last):
  File "/home/airflow/.local/lib/python3.7/site-packages/airflow/models/dagbag.py", line 339, in parse
    loader.exec_module(new_module)
  File "<frozen importlib._bootstrap_external>", line 728, in exec_module
  File "<frozen importlib._bootstrap>", line 219, in _call_with_frames_removed
  File "/opt/airflow/dags/etlcommands.py", line 46, in <module>
    capture_account_data >> is_valid >> [valid, nvalid]
NameError: name 'nvalid' is not defined
[2023-01-26T17:30:47.772+0000] {processor.py:755} WARNING - No viable dags retrieved from /opt/airflow/dags/etlcommands.py
[2023-01-26T17:30:47.797+0000] {processor.py:175} INFO - Processing /opt/airflow/dags/etlcommands.py took 0.265 seconds
[2023-01-26T17:31:18.542+0000] {processor.py:153} INFO - Started process (PID=2219) to work on /opt/airflow/dags/etlcommands.py
[2023-01-26T17:31:18.542+0000] {processor.py:743} INFO - Processing file /opt/airflow/dags/etlcommands.py for tasks to queue
[2023-01-26T17:31:18.543+0000] {logging_mixin.py:137} INFO - [2023-01-26T17:31:18.543+0000] {dagbag.py:538} INFO - Filling up the DagBag from /opt/airflow/dags/etlcommands.py
[2023-01-26T17:31:18.883+0000] {logging_mixin.py:137} INFO - [2023-01-26T17:31:18.882+0000] {dagbag.py:343} ERROR - Failed to import: /opt/airflow/dags/etlcommands.py
Traceback (most recent call last):
  File "/home/airflow/.local/lib/python3.7/site-packages/airflow/models/dagbag.py", line 339, in parse
    loader.exec_module(new_module)
  File "<frozen importlib._bootstrap_external>", line 728, in exec_module
  File "<frozen importlib._bootstrap>", line 219, in _call_with_frames_removed
  File "/opt/airflow/dags/etlcommands.py", line 46, in <module>
    capture_account_data >> is_valid >> [valid, nvalid]
NameError: name 'nvalid' is not defined
[2023-01-26T17:31:18.884+0000] {processor.py:755} WARNING - No viable dags retrieved from /opt/airflow/dags/etlcommands.py
[2023-01-26T17:31:18.912+0000] {processor.py:175} INFO - Processing /opt/airflow/dags/etlcommands.py took 0.374 seconds
[2023-01-26T17:31:49.009+0000] {processor.py:153} INFO - Started process (PID=2286) to work on /opt/airflow/dags/etlcommands.py
[2023-01-26T17:31:49.010+0000] {processor.py:743} INFO - Processing file /opt/airflow/dags/etlcommands.py for tasks to queue
[2023-01-26T17:31:49.011+0000] {logging_mixin.py:137} INFO - [2023-01-26T17:31:49.011+0000] {dagbag.py:538} INFO - Filling up the DagBag from /opt/airflow/dags/etlcommands.py
[2023-01-26T17:31:49.230+0000] {logging_mixin.py:137} INFO - [2023-01-26T17:31:49.229+0000] {dagbag.py:343} ERROR - Failed to import: /opt/airflow/dags/etlcommands.py
Traceback (most recent call last):
  File "/home/airflow/.local/lib/python3.7/site-packages/airflow/models/dagbag.py", line 339, in parse
    loader.exec_module(new_module)
  File "<frozen importlib._bootstrap_external>", line 728, in exec_module
  File "<frozen importlib._bootstrap>", line 219, in _call_with_frames_removed
  File "/opt/airflow/dags/etlcommands.py", line 46, in <module>
    capture_account_data >> is_valid >> [valid, nvalid]
NameError: name 'nvalid' is not defined
[2023-01-26T17:31:49.230+0000] {processor.py:755} WARNING - No viable dags retrieved from /opt/airflow/dags/etlcommands.py
[2023-01-26T17:31:49.256+0000] {processor.py:175} INFO - Processing /opt/airflow/dags/etlcommands.py took 0.251 seconds
[2023-01-26T17:32:20.137+0000] {processor.py:153} INFO - Started process (PID=2362) to work on /opt/airflow/dags/etlcommands.py
[2023-01-26T17:32:20.139+0000] {processor.py:743} INFO - Processing file /opt/airflow/dags/etlcommands.py for tasks to queue
[2023-01-26T17:32:20.140+0000] {logging_mixin.py:137} INFO - [2023-01-26T17:32:20.139+0000] {dagbag.py:538} INFO - Filling up the DagBag from /opt/airflow/dags/etlcommands.py
[2023-01-26T17:32:20.396+0000] {logging_mixin.py:137} INFO - [2023-01-26T17:32:20.395+0000] {dagbag.py:343} ERROR - Failed to import: /opt/airflow/dags/etlcommands.py
Traceback (most recent call last):
  File "/home/airflow/.local/lib/python3.7/site-packages/airflow/models/dagbag.py", line 339, in parse
    loader.exec_module(new_module)
  File "<frozen importlib._bootstrap_external>", line 728, in exec_module
  File "<frozen importlib._bootstrap>", line 219, in _call_with_frames_removed
  File "/opt/airflow/dags/etlcommands.py", line 46, in <module>
    capture_account_data >> is_valid >> [valid, nvalid]
NameError: name 'nvalid' is not defined
[2023-01-26T17:32:20.397+0000] {processor.py:755} WARNING - No viable dags retrieved from /opt/airflow/dags/etlcommands.py
[2023-01-26T17:32:20.422+0000] {processor.py:175} INFO - Processing /opt/airflow/dags/etlcommands.py took 0.289 seconds
[2023-01-26T17:32:50.694+0000] {processor.py:153} INFO - Started process (PID=2429) to work on /opt/airflow/dags/etlcommands.py
[2023-01-26T17:32:50.695+0000] {processor.py:743} INFO - Processing file /opt/airflow/dags/etlcommands.py for tasks to queue
[2023-01-26T17:32:50.696+0000] {logging_mixin.py:137} INFO - [2023-01-26T17:32:50.696+0000] {dagbag.py:538} INFO - Filling up the DagBag from /opt/airflow/dags/etlcommands.py
[2023-01-26T17:32:50.963+0000] {logging_mixin.py:137} INFO - [2023-01-26T17:32:50.963+0000] {dagbag.py:343} ERROR - Failed to import: /opt/airflow/dags/etlcommands.py
Traceback (most recent call last):
  File "/home/airflow/.local/lib/python3.7/site-packages/airflow/models/dagbag.py", line 339, in parse
    loader.exec_module(new_module)
  File "<frozen importlib._bootstrap_external>", line 728, in exec_module
  File "<frozen importlib._bootstrap>", line 219, in _call_with_frames_removed
  File "/opt/airflow/dags/etlcommands.py", line 46, in <module>
    capture_account_data >> is_valid >> [valid, nvalid]
NameError: name 'nvalid' is not defined
[2023-01-26T17:32:50.964+0000] {processor.py:755} WARNING - No viable dags retrieved from /opt/airflow/dags/etlcommands.py
[2023-01-26T17:32:50.989+0000] {processor.py:175} INFO - Processing /opt/airflow/dags/etlcommands.py took 0.299 seconds
[2023-01-26T17:33:21.087+0000] {processor.py:153} INFO - Started process (PID=2507) to work on /opt/airflow/dags/etlcommands.py
[2023-01-26T17:33:21.087+0000] {processor.py:743} INFO - Processing file /opt/airflow/dags/etlcommands.py for tasks to queue
[2023-01-26T17:33:21.088+0000] {logging_mixin.py:137} INFO - [2023-01-26T17:33:21.088+0000] {dagbag.py:538} INFO - Filling up the DagBag from /opt/airflow/dags/etlcommands.py
[2023-01-26T17:33:21.382+0000] {logging_mixin.py:137} INFO - [2023-01-26T17:33:21.381+0000] {dagbag.py:343} ERROR - Failed to import: /opt/airflow/dags/etlcommands.py
Traceback (most recent call last):
  File "/home/airflow/.local/lib/python3.7/site-packages/airflow/models/dagbag.py", line 339, in parse
    loader.exec_module(new_module)
  File "<frozen importlib._bootstrap_external>", line 728, in exec_module
  File "<frozen importlib._bootstrap>", line 219, in _call_with_frames_removed
  File "/opt/airflow/dags/etlcommands.py", line 46, in <module>
    capture_account_data >> is_valid >> [valid, nvalid]
NameError: name 'nvalid' is not defined
[2023-01-26T17:33:21.382+0000] {processor.py:755} WARNING - No viable dags retrieved from /opt/airflow/dags/etlcommands.py
[2023-01-26T17:33:21.421+0000] {processor.py:175} INFO - Processing /opt/airflow/dags/etlcommands.py took 0.338 seconds
[2023-01-26T17:33:51.795+0000] {processor.py:153} INFO - Started process (PID=2571) to work on /opt/airflow/dags/etlcommands.py
[2023-01-26T17:33:51.795+0000] {processor.py:743} INFO - Processing file /opt/airflow/dags/etlcommands.py for tasks to queue
[2023-01-26T17:33:51.796+0000] {logging_mixin.py:137} INFO - [2023-01-26T17:33:51.796+0000] {dagbag.py:538} INFO - Filling up the DagBag from /opt/airflow/dags/etlcommands.py
[2023-01-26T17:33:52.020+0000] {logging_mixin.py:137} INFO - [2023-01-26T17:33:52.020+0000] {dagbag.py:343} ERROR - Failed to import: /opt/airflow/dags/etlcommands.py
Traceback (most recent call last):
  File "/home/airflow/.local/lib/python3.7/site-packages/airflow/models/dagbag.py", line 339, in parse
    loader.exec_module(new_module)
  File "<frozen importlib._bootstrap_external>", line 728, in exec_module
  File "<frozen importlib._bootstrap>", line 219, in _call_with_frames_removed
  File "/opt/airflow/dags/etlcommands.py", line 46, in <module>
    capture_account_data >> is_valid >> [valid, nvalid]
NameError: name 'nvalid' is not defined
[2023-01-26T17:33:52.021+0000] {processor.py:755} WARNING - No viable dags retrieved from /opt/airflow/dags/etlcommands.py
[2023-01-26T17:33:52.044+0000] {processor.py:175} INFO - Processing /opt/airflow/dags/etlcommands.py took 0.252 seconds
[2023-01-26T17:34:22.665+0000] {processor.py:153} INFO - Started process (PID=2648) to work on /opt/airflow/dags/etlcommands.py
[2023-01-26T17:34:22.666+0000] {processor.py:743} INFO - Processing file /opt/airflow/dags/etlcommands.py for tasks to queue
[2023-01-26T17:34:22.667+0000] {logging_mixin.py:137} INFO - [2023-01-26T17:34:22.667+0000] {dagbag.py:538} INFO - Filling up the DagBag from /opt/airflow/dags/etlcommands.py
[2023-01-26T17:34:22.923+0000] {logging_mixin.py:137} INFO - [2023-01-26T17:34:22.923+0000] {dagbag.py:343} ERROR - Failed to import: /opt/airflow/dags/etlcommands.py
Traceback (most recent call last):
  File "/home/airflow/.local/lib/python3.7/site-packages/airflow/models/dagbag.py", line 339, in parse
    loader.exec_module(new_module)
  File "<frozen importlib._bootstrap_external>", line 728, in exec_module
  File "<frozen importlib._bootstrap>", line 219, in _call_with_frames_removed
  File "/opt/airflow/dags/etlcommands.py", line 46, in <module>
    capture_account_data >> is_valid >> [valid, nvalid]
NameError: name 'nvalid' is not defined
[2023-01-26T17:34:22.924+0000] {processor.py:755} WARNING - No viable dags retrieved from /opt/airflow/dags/etlcommands.py
[2023-01-26T17:34:22.946+0000] {processor.py:175} INFO - Processing /opt/airflow/dags/etlcommands.py took 0.284 seconds
[2023-01-26T17:34:53.222+0000] {processor.py:153} INFO - Started process (PID=2713) to work on /opt/airflow/dags/etlcommands.py
[2023-01-26T17:34:53.223+0000] {processor.py:743} INFO - Processing file /opt/airflow/dags/etlcommands.py for tasks to queue
[2023-01-26T17:34:53.224+0000] {logging_mixin.py:137} INFO - [2023-01-26T17:34:53.224+0000] {dagbag.py:538} INFO - Filling up the DagBag from /opt/airflow/dags/etlcommands.py
[2023-01-26T17:34:53.449+0000] {logging_mixin.py:137} INFO - [2023-01-26T17:34:53.448+0000] {dagbag.py:343} ERROR - Failed to import: /opt/airflow/dags/etlcommands.py
Traceback (most recent call last):
  File "/home/airflow/.local/lib/python3.7/site-packages/airflow/models/dagbag.py", line 339, in parse
    loader.exec_module(new_module)
  File "<frozen importlib._bootstrap_external>", line 728, in exec_module
  File "<frozen importlib._bootstrap>", line 219, in _call_with_frames_removed
  File "/opt/airflow/dags/etlcommands.py", line 46, in <module>
    capture_account_data >> is_valid >> [valid, nvalid]
NameError: name 'nvalid' is not defined
[2023-01-26T17:34:53.449+0000] {processor.py:755} WARNING - No viable dags retrieved from /opt/airflow/dags/etlcommands.py
[2023-01-26T17:34:53.505+0000] {processor.py:175} INFO - Processing /opt/airflow/dags/etlcommands.py took 0.286 seconds
[2023-01-26T17:35:23.569+0000] {processor.py:153} INFO - Started process (PID=2791) to work on /opt/airflow/dags/etlcommands.py
[2023-01-26T17:35:23.570+0000] {processor.py:743} INFO - Processing file /opt/airflow/dags/etlcommands.py for tasks to queue
[2023-01-26T17:35:23.571+0000] {logging_mixin.py:137} INFO - [2023-01-26T17:35:23.571+0000] {dagbag.py:538} INFO - Filling up the DagBag from /opt/airflow/dags/etlcommands.py
[2023-01-26T17:35:23.817+0000] {logging_mixin.py:137} INFO - [2023-01-26T17:35:23.816+0000] {dagbag.py:343} ERROR - Failed to import: /opt/airflow/dags/etlcommands.py
Traceback (most recent call last):
  File "/home/airflow/.local/lib/python3.7/site-packages/airflow/models/dagbag.py", line 339, in parse
    loader.exec_module(new_module)
  File "<frozen importlib._bootstrap_external>", line 728, in exec_module
  File "<frozen importlib._bootstrap>", line 219, in _call_with_frames_removed
  File "/opt/airflow/dags/etlcommands.py", line 46, in <module>
    capture_account_data >> is_valid >> [valid, nvalid]
NameError: name 'nvalid' is not defined
[2023-01-26T17:35:23.818+0000] {processor.py:755} WARNING - No viable dags retrieved from /opt/airflow/dags/etlcommands.py
[2023-01-26T17:35:23.841+0000] {processor.py:175} INFO - Processing /opt/airflow/dags/etlcommands.py took 0.275 seconds
[2023-01-26T17:35:54.233+0000] {processor.py:153} INFO - Started process (PID=2856) to work on /opt/airflow/dags/etlcommands.py
[2023-01-26T17:35:54.234+0000] {processor.py:743} INFO - Processing file /opt/airflow/dags/etlcommands.py for tasks to queue
[2023-01-26T17:35:54.235+0000] {logging_mixin.py:137} INFO - [2023-01-26T17:35:54.234+0000] {dagbag.py:538} INFO - Filling up the DagBag from /opt/airflow/dags/etlcommands.py
[2023-01-26T17:35:54.458+0000] {logging_mixin.py:137} INFO - [2023-01-26T17:35:54.457+0000] {dagbag.py:343} ERROR - Failed to import: /opt/airflow/dags/etlcommands.py
Traceback (most recent call last):
  File "/home/airflow/.local/lib/python3.7/site-packages/airflow/models/dagbag.py", line 339, in parse
    loader.exec_module(new_module)
  File "<frozen importlib._bootstrap_external>", line 728, in exec_module
  File "<frozen importlib._bootstrap>", line 219, in _call_with_frames_removed
  File "/opt/airflow/dags/etlcommands.py", line 46, in <module>
    capture_account_data >> is_valid >> [valid, nvalid]
NameError: name 'nvalid' is not defined
[2023-01-26T17:35:54.458+0000] {processor.py:755} WARNING - No viable dags retrieved from /opt/airflow/dags/etlcommands.py
[2023-01-26T17:35:54.482+0000] {processor.py:175} INFO - Processing /opt/airflow/dags/etlcommands.py took 0.253 seconds
[2023-01-26T17:36:25.123+0000] {processor.py:153} INFO - Started process (PID=2933) to work on /opt/airflow/dags/etlcommands.py
[2023-01-26T17:36:25.123+0000] {processor.py:743} INFO - Processing file /opt/airflow/dags/etlcommands.py for tasks to queue
[2023-01-26T17:36:25.124+0000] {logging_mixin.py:137} INFO - [2023-01-26T17:36:25.124+0000] {dagbag.py:538} INFO - Filling up the DagBag from /opt/airflow/dags/etlcommands.py
[2023-01-26T17:36:25.353+0000] {logging_mixin.py:137} INFO - [2023-01-26T17:36:25.353+0000] {dagbag.py:343} ERROR - Failed to import: /opt/airflow/dags/etlcommands.py
Traceback (most recent call last):
  File "/home/airflow/.local/lib/python3.7/site-packages/airflow/models/dagbag.py", line 339, in parse
    loader.exec_module(new_module)
  File "<frozen importlib._bootstrap_external>", line 728, in exec_module
  File "<frozen importlib._bootstrap>", line 219, in _call_with_frames_removed
  File "/opt/airflow/dags/etlcommands.py", line 46, in <module>
    capture_account_data >> is_valid >> [valid, nvalid]
NameError: name 'nvalid' is not defined
[2023-01-26T17:36:25.354+0000] {processor.py:755} WARNING - No viable dags retrieved from /opt/airflow/dags/etlcommands.py
[2023-01-26T17:36:25.378+0000] {processor.py:175} INFO - Processing /opt/airflow/dags/etlcommands.py took 0.259 seconds
[2023-01-26T17:36:55.836+0000] {processor.py:153} INFO - Started process (PID=2998) to work on /opt/airflow/dags/etlcommands.py
[2023-01-26T17:36:55.837+0000] {processor.py:743} INFO - Processing file /opt/airflow/dags/etlcommands.py for tasks to queue
[2023-01-26T17:36:55.838+0000] {logging_mixin.py:137} INFO - [2023-01-26T17:36:55.838+0000] {dagbag.py:538} INFO - Filling up the DagBag from /opt/airflow/dags/etlcommands.py
[2023-01-26T17:36:56.098+0000] {logging_mixin.py:137} INFO - [2023-01-26T17:36:56.097+0000] {dagbag.py:343} ERROR - Failed to import: /opt/airflow/dags/etlcommands.py
Traceback (most recent call last):
  File "/home/airflow/.local/lib/python3.7/site-packages/airflow/models/dagbag.py", line 339, in parse
    loader.exec_module(new_module)
  File "<frozen importlib._bootstrap_external>", line 728, in exec_module
  File "<frozen importlib._bootstrap>", line 219, in _call_with_frames_removed
  File "/opt/airflow/dags/etlcommands.py", line 46, in <module>
    capture_account_data >> is_valid >> [valid, nvalid]
NameError: name 'nvalid' is not defined
[2023-01-26T17:36:56.099+0000] {processor.py:755} WARNING - No viable dags retrieved from /opt/airflow/dags/etlcommands.py
[2023-01-26T17:36:56.127+0000] {processor.py:175} INFO - Processing /opt/airflow/dags/etlcommands.py took 0.295 seconds
[2023-01-26T17:37:26.869+0000] {processor.py:153} INFO - Started process (PID=3075) to work on /opt/airflow/dags/etlcommands.py
[2023-01-26T17:37:26.870+0000] {processor.py:743} INFO - Processing file /opt/airflow/dags/etlcommands.py for tasks to queue
[2023-01-26T17:37:26.871+0000] {logging_mixin.py:137} INFO - [2023-01-26T17:37:26.871+0000] {dagbag.py:538} INFO - Filling up the DagBag from /opt/airflow/dags/etlcommands.py
[2023-01-26T17:37:27.125+0000] {logging_mixin.py:137} INFO - [2023-01-26T17:37:27.124+0000] {dagbag.py:343} ERROR - Failed to import: /opt/airflow/dags/etlcommands.py
Traceback (most recent call last):
  File "/home/airflow/.local/lib/python3.7/site-packages/airflow/models/dagbag.py", line 339, in parse
    loader.exec_module(new_module)
  File "<frozen importlib._bootstrap_external>", line 728, in exec_module
  File "<frozen importlib._bootstrap>", line 219, in _call_with_frames_removed
  File "/opt/airflow/dags/etlcommands.py", line 46, in <module>
    capture_account_data >> is_valid >> [valid, nvalid]
NameError: name 'nvalid' is not defined
[2023-01-26T17:37:27.126+0000] {processor.py:755} WARNING - No viable dags retrieved from /opt/airflow/dags/etlcommands.py
[2023-01-26T17:37:27.153+0000] {processor.py:175} INFO - Processing /opt/airflow/dags/etlcommands.py took 0.287 seconds
[2023-01-26T17:37:57.618+0000] {processor.py:153} INFO - Started process (PID=3140) to work on /opt/airflow/dags/etlcommands.py
[2023-01-26T17:37:57.619+0000] {processor.py:743} INFO - Processing file /opt/airflow/dags/etlcommands.py for tasks to queue
[2023-01-26T17:37:57.620+0000] {logging_mixin.py:137} INFO - [2023-01-26T17:37:57.619+0000] {dagbag.py:538} INFO - Filling up the DagBag from /opt/airflow/dags/etlcommands.py
[2023-01-26T17:37:57.898+0000] {logging_mixin.py:137} INFO - [2023-01-26T17:37:57.897+0000] {dagbag.py:343} ERROR - Failed to import: /opt/airflow/dags/etlcommands.py
Traceback (most recent call last):
  File "/home/airflow/.local/lib/python3.7/site-packages/airflow/models/dagbag.py", line 339, in parse
    loader.exec_module(new_module)
  File "<frozen importlib._bootstrap_external>", line 728, in exec_module
  File "<frozen importlib._bootstrap>", line 219, in _call_with_frames_removed
  File "/opt/airflow/dags/etlcommands.py", line 46, in <module>
    capture_account_data >> is_valid >> [valid, nvalid]
NameError: name 'nvalid' is not defined
[2023-01-26T17:37:57.899+0000] {processor.py:755} WARNING - No viable dags retrieved from /opt/airflow/dags/etlcommands.py
[2023-01-26T17:37:57.925+0000] {processor.py:175} INFO - Processing /opt/airflow/dags/etlcommands.py took 0.310 seconds
[2023-01-26T17:38:28.049+0000] {processor.py:153} INFO - Started process (PID=3218) to work on /opt/airflow/dags/etlcommands.py
[2023-01-26T17:38:28.052+0000] {processor.py:743} INFO - Processing file /opt/airflow/dags/etlcommands.py for tasks to queue
[2023-01-26T17:38:28.053+0000] {logging_mixin.py:137} INFO - [2023-01-26T17:38:28.053+0000] {dagbag.py:538} INFO - Filling up the DagBag from /opt/airflow/dags/etlcommands.py
[2023-01-26T17:38:28.606+0000] {logging_mixin.py:137} INFO - [2023-01-26T17:38:28.605+0000] {dagbag.py:343} ERROR - Failed to import: /opt/airflow/dags/etlcommands.py
Traceback (most recent call last):
  File "/home/airflow/.local/lib/python3.7/site-packages/airflow/models/dagbag.py", line 339, in parse
    loader.exec_module(new_module)
  File "<frozen importlib._bootstrap_external>", line 728, in exec_module
  File "<frozen importlib._bootstrap>", line 219, in _call_with_frames_removed
  File "/opt/airflow/dags/etlcommands.py", line 46, in <module>
    capture_account_data >> is_valid >> [valid, nvalid]
NameError: name 'nvalid' is not defined
[2023-01-26T17:38:28.607+0000] {processor.py:755} WARNING - No viable dags retrieved from /opt/airflow/dags/etlcommands.py
[2023-01-26T17:38:28.630+0000] {processor.py:175} INFO - Processing /opt/airflow/dags/etlcommands.py took 0.586 seconds
[2023-01-26T17:38:58.989+0000] {processor.py:153} INFO - Started process (PID=3283) to work on /opt/airflow/dags/etlcommands.py
[2023-01-26T17:38:58.990+0000] {processor.py:743} INFO - Processing file /opt/airflow/dags/etlcommands.py for tasks to queue
[2023-01-26T17:38:58.990+0000] {logging_mixin.py:137} INFO - [2023-01-26T17:38:58.990+0000] {dagbag.py:538} INFO - Filling up the DagBag from /opt/airflow/dags/etlcommands.py
[2023-01-26T17:38:59.222+0000] {logging_mixin.py:137} INFO - [2023-01-26T17:38:59.221+0000] {dagbag.py:343} ERROR - Failed to import: /opt/airflow/dags/etlcommands.py
Traceback (most recent call last):
  File "/home/airflow/.local/lib/python3.7/site-packages/airflow/models/dagbag.py", line 339, in parse
    loader.exec_module(new_module)
  File "<frozen importlib._bootstrap_external>", line 728, in exec_module
  File "<frozen importlib._bootstrap>", line 219, in _call_with_frames_removed
  File "/opt/airflow/dags/etlcommands.py", line 46, in <module>
    capture_account_data >> is_valid >> [valid, nvalid]
NameError: name 'nvalid' is not defined
[2023-01-26T17:38:59.222+0000] {processor.py:755} WARNING - No viable dags retrieved from /opt/airflow/dags/etlcommands.py
[2023-01-26T17:38:59.244+0000] {processor.py:175} INFO - Processing /opt/airflow/dags/etlcommands.py took 0.258 seconds
[2023-01-26T17:39:29.395+0000] {processor.py:153} INFO - Started process (PID=3362) to work on /opt/airflow/dags/etlcommands.py
[2023-01-26T17:39:29.396+0000] {processor.py:743} INFO - Processing file /opt/airflow/dags/etlcommands.py for tasks to queue
[2023-01-26T17:39:29.397+0000] {logging_mixin.py:137} INFO - [2023-01-26T17:39:29.396+0000] {dagbag.py:538} INFO - Filling up the DagBag from /opt/airflow/dags/etlcommands.py
[2023-01-26T17:39:29.729+0000] {logging_mixin.py:137} INFO - [2023-01-26T17:39:29.728+0000] {dagbag.py:343} ERROR - Failed to import: /opt/airflow/dags/etlcommands.py
Traceback (most recent call last):
  File "/home/airflow/.local/lib/python3.7/site-packages/airflow/models/dagbag.py", line 339, in parse
    loader.exec_module(new_module)
  File "<frozen importlib._bootstrap_external>", line 728, in exec_module
  File "<frozen importlib._bootstrap>", line 219, in _call_with_frames_removed
  File "/opt/airflow/dags/etlcommands.py", line 46, in <module>
    capture_account_data >> is_valid >> [valid, nvalid]
NameError: name 'nvalid' is not defined
[2023-01-26T17:39:29.730+0000] {processor.py:755} WARNING - No viable dags retrieved from /opt/airflow/dags/etlcommands.py
[2023-01-26T17:39:29.763+0000] {processor.py:175} INFO - Processing /opt/airflow/dags/etlcommands.py took 0.373 seconds
[2023-01-26T17:39:59.787+0000] {processor.py:153} INFO - Started process (PID=3429) to work on /opt/airflow/dags/etlcommands.py
[2023-01-26T17:39:59.788+0000] {processor.py:743} INFO - Processing file /opt/airflow/dags/etlcommands.py for tasks to queue
[2023-01-26T17:39:59.789+0000] {logging_mixin.py:137} INFO - [2023-01-26T17:39:59.789+0000] {dagbag.py:538} INFO - Filling up the DagBag from /opt/airflow/dags/etlcommands.py
[2023-01-26T17:40:00.001+0000] {logging_mixin.py:137} INFO - [2023-01-26T17:40:00.000+0000] {dagbag.py:343} ERROR - Failed to import: /opt/airflow/dags/etlcommands.py
Traceback (most recent call last):
  File "/home/airflow/.local/lib/python3.7/site-packages/airflow/models/dagbag.py", line 339, in parse
    loader.exec_module(new_module)
  File "<frozen importlib._bootstrap_external>", line 728, in exec_module
  File "<frozen importlib._bootstrap>", line 219, in _call_with_frames_removed
  File "/opt/airflow/dags/etlcommands.py", line 46, in <module>
    capture_account_data >> is_valid >> [valid, nvalid]
NameError: name 'nvalid' is not defined
[2023-01-26T17:40:00.001+0000] {processor.py:755} WARNING - No viable dags retrieved from /opt/airflow/dags/etlcommands.py
[2023-01-26T17:40:00.025+0000] {processor.py:175} INFO - Processing /opt/airflow/dags/etlcommands.py took 0.241 seconds
[2023-01-26T17:40:30.933+0000] {processor.py:153} INFO - Started process (PID=3507) to work on /opt/airflow/dags/etlcommands.py
[2023-01-26T17:40:30.934+0000] {processor.py:743} INFO - Processing file /opt/airflow/dags/etlcommands.py for tasks to queue
[2023-01-26T17:40:30.935+0000] {logging_mixin.py:137} INFO - [2023-01-26T17:40:30.934+0000] {dagbag.py:538} INFO - Filling up the DagBag from /opt/airflow/dags/etlcommands.py
[2023-01-26T17:40:31.223+0000] {logging_mixin.py:137} INFO - [2023-01-26T17:40:31.222+0000] {dagbag.py:343} ERROR - Failed to import: /opt/airflow/dags/etlcommands.py
Traceback (most recent call last):
  File "/home/airflow/.local/lib/python3.7/site-packages/airflow/models/dagbag.py", line 339, in parse
    loader.exec_module(new_module)
  File "<frozen importlib._bootstrap_external>", line 728, in exec_module
  File "<frozen importlib._bootstrap>", line 219, in _call_with_frames_removed
  File "/opt/airflow/dags/etlcommands.py", line 46, in <module>
    capture_account_data >> is_valid >> [valid, nvalid]
NameError: name 'nvalid' is not defined
[2023-01-26T17:40:31.223+0000] {processor.py:755} WARNING - No viable dags retrieved from /opt/airflow/dags/etlcommands.py
[2023-01-26T17:40:31.247+0000] {processor.py:175} INFO - Processing /opt/airflow/dags/etlcommands.py took 0.319 seconds
[2023-01-26T17:41:01.902+0000] {processor.py:153} INFO - Started process (PID=3572) to work on /opt/airflow/dags/etlcommands.py
[2023-01-26T17:41:01.903+0000] {processor.py:743} INFO - Processing file /opt/airflow/dags/etlcommands.py for tasks to queue
[2023-01-26T17:41:01.903+0000] {logging_mixin.py:137} INFO - [2023-01-26T17:41:01.903+0000] {dagbag.py:538} INFO - Filling up the DagBag from /opt/airflow/dags/etlcommands.py
[2023-01-26T17:41:02.161+0000] {logging_mixin.py:137} INFO - [2023-01-26T17:41:02.160+0000] {dagbag.py:343} ERROR - Failed to import: /opt/airflow/dags/etlcommands.py
Traceback (most recent call last):
  File "/home/airflow/.local/lib/python3.7/site-packages/airflow/models/dagbag.py", line 339, in parse
    loader.exec_module(new_module)
  File "<frozen importlib._bootstrap_external>", line 728, in exec_module
  File "<frozen importlib._bootstrap>", line 219, in _call_with_frames_removed
  File "/opt/airflow/dags/etlcommands.py", line 46, in <module>
    capture_account_data >> is_valid >> [valid, nvalid]
NameError: name 'nvalid' is not defined
[2023-01-26T17:41:02.161+0000] {processor.py:755} WARNING - No viable dags retrieved from /opt/airflow/dags/etlcommands.py
[2023-01-26T17:41:02.184+0000] {processor.py:175} INFO - Processing /opt/airflow/dags/etlcommands.py took 0.286 seconds
[2023-01-26T17:41:32.594+0000] {processor.py:153} INFO - Started process (PID=3651) to work on /opt/airflow/dags/etlcommands.py
[2023-01-26T17:41:32.595+0000] {processor.py:743} INFO - Processing file /opt/airflow/dags/etlcommands.py for tasks to queue
[2023-01-26T17:41:32.596+0000] {logging_mixin.py:137} INFO - [2023-01-26T17:41:32.595+0000] {dagbag.py:538} INFO - Filling up the DagBag from /opt/airflow/dags/etlcommands.py
[2023-01-26T17:41:33.014+0000] {logging_mixin.py:137} INFO - [2023-01-26T17:41:33.006+0000] {dagbag.py:343} ERROR - Failed to import: /opt/airflow/dags/etlcommands.py
Traceback (most recent call last):
  File "/home/airflow/.local/lib/python3.7/site-packages/airflow/models/dagbag.py", line 339, in parse
    loader.exec_module(new_module)
  File "<frozen importlib._bootstrap_external>", line 728, in exec_module
  File "<frozen importlib._bootstrap>", line 219, in _call_with_frames_removed
  File "/opt/airflow/dags/etlcommands.py", line 46, in <module>
    capture_account_data >> is_valid >> [valid, nvalid]
NameError: name 'nvalid' is not defined
[2023-01-26T17:41:33.014+0000] {processor.py:755} WARNING - No viable dags retrieved from /opt/airflow/dags/etlcommands.py
[2023-01-26T17:41:33.069+0000] {processor.py:175} INFO - Processing /opt/airflow/dags/etlcommands.py took 0.480 seconds
[2023-01-26T17:42:03.118+0000] {processor.py:153} INFO - Started process (PID=3718) to work on /opt/airflow/dags/etlcommands.py
[2023-01-26T17:42:03.119+0000] {processor.py:743} INFO - Processing file /opt/airflow/dags/etlcommands.py for tasks to queue
[2023-01-26T17:42:03.120+0000] {logging_mixin.py:137} INFO - [2023-01-26T17:42:03.120+0000] {dagbag.py:538} INFO - Filling up the DagBag from /opt/airflow/dags/etlcommands.py
[2023-01-26T17:42:03.335+0000] {logging_mixin.py:137} INFO - [2023-01-26T17:42:03.334+0000] {dagbag.py:343} ERROR - Failed to import: /opt/airflow/dags/etlcommands.py
Traceback (most recent call last):
  File "/home/airflow/.local/lib/python3.7/site-packages/airflow/models/dagbag.py", line 339, in parse
    loader.exec_module(new_module)
  File "<frozen importlib._bootstrap_external>", line 728, in exec_module
  File "<frozen importlib._bootstrap>", line 219, in _call_with_frames_removed
  File "/opt/airflow/dags/etlcommands.py", line 46, in <module>
    capture_account_data >> is_valid >> [valid, nvalid]
NameError: name 'nvalid' is not defined
[2023-01-26T17:42:03.335+0000] {processor.py:755} WARNING - No viable dags retrieved from /opt/airflow/dags/etlcommands.py
[2023-01-26T17:42:03.359+0000] {processor.py:175} INFO - Processing /opt/airflow/dags/etlcommands.py took 0.243 seconds
[2023-01-26T17:42:33.493+0000] {processor.py:153} INFO - Started process (PID=3789) to work on /opt/airflow/dags/etlcommands.py
[2023-01-26T17:42:33.494+0000] {processor.py:743} INFO - Processing file /opt/airflow/dags/etlcommands.py for tasks to queue
[2023-01-26T17:42:33.495+0000] {logging_mixin.py:137} INFO - [2023-01-26T17:42:33.494+0000] {dagbag.py:538} INFO - Filling up the DagBag from /opt/airflow/dags/etlcommands.py
[2023-01-26T17:42:33.842+0000] {logging_mixin.py:137} INFO - [2023-01-26T17:42:33.841+0000] {dagbag.py:343} ERROR - Failed to import: /opt/airflow/dags/etlcommands.py
Traceback (most recent call last):
  File "/home/airflow/.local/lib/python3.7/site-packages/airflow/models/dagbag.py", line 339, in parse
    loader.exec_module(new_module)
  File "<frozen importlib._bootstrap_external>", line 728, in exec_module
  File "<frozen importlib._bootstrap>", line 219, in _call_with_frames_removed
  File "/opt/airflow/dags/etlcommands.py", line 46, in <module>
    capture_account_data >> is_valid >> [valid, nvalid]
NameError: name 'nvalid' is not defined
[2023-01-26T17:42:33.843+0000] {processor.py:755} WARNING - No viable dags retrieved from /opt/airflow/dags/etlcommands.py
[2023-01-26T17:42:33.872+0000] {processor.py:175} INFO - Processing /opt/airflow/dags/etlcommands.py took 0.384 seconds
[2023-01-26T17:43:03.955+0000] {processor.py:153} INFO - Started process (PID=3861) to work on /opt/airflow/dags/etlcommands.py
[2023-01-26T17:43:03.956+0000] {processor.py:743} INFO - Processing file /opt/airflow/dags/etlcommands.py for tasks to queue
[2023-01-26T17:43:03.956+0000] {logging_mixin.py:137} INFO - [2023-01-26T17:43:03.956+0000] {dagbag.py:538} INFO - Filling up the DagBag from /opt/airflow/dags/etlcommands.py
[2023-01-26T17:43:04.179+0000] {logging_mixin.py:137} INFO - [2023-01-26T17:43:04.178+0000] {dagbag.py:343} ERROR - Failed to import: /opt/airflow/dags/etlcommands.py
Traceback (most recent call last):
  File "/home/airflow/.local/lib/python3.7/site-packages/airflow/models/dagbag.py", line 339, in parse
    loader.exec_module(new_module)
  File "<frozen importlib._bootstrap_external>", line 728, in exec_module
  File "<frozen importlib._bootstrap>", line 219, in _call_with_frames_removed
  File "/opt/airflow/dags/etlcommands.py", line 46, in <module>
    capture_account_data >> is_valid >> [valid, nvalid]
NameError: name 'nvalid' is not defined
[2023-01-26T17:43:04.179+0000] {processor.py:755} WARNING - No viable dags retrieved from /opt/airflow/dags/etlcommands.py
[2023-01-26T17:43:04.205+0000] {processor.py:175} INFO - Processing /opt/airflow/dags/etlcommands.py took 0.254 seconds
[2023-01-26T17:43:35.186+0000] {processor.py:153} INFO - Started process (PID=3934) to work on /opt/airflow/dags/etlcommands.py
[2023-01-26T17:43:35.190+0000] {processor.py:743} INFO - Processing file /opt/airflow/dags/etlcommands.py for tasks to queue
[2023-01-26T17:43:35.190+0000] {logging_mixin.py:137} INFO - [2023-01-26T17:43:35.190+0000] {dagbag.py:538} INFO - Filling up the DagBag from /opt/airflow/dags/etlcommands.py
[2023-01-26T17:43:35.450+0000] {logging_mixin.py:137} INFO - [2023-01-26T17:43:35.449+0000] {dagbag.py:343} ERROR - Failed to import: /opt/airflow/dags/etlcommands.py
Traceback (most recent call last):
  File "/home/airflow/.local/lib/python3.7/site-packages/airflow/models/dagbag.py", line 339, in parse
    loader.exec_module(new_module)
  File "<frozen importlib._bootstrap_external>", line 728, in exec_module
  File "<frozen importlib._bootstrap>", line 219, in _call_with_frames_removed
  File "/opt/airflow/dags/etlcommands.py", line 46, in <module>
    capture_account_data >> is_valid >> [valid, nvalid]
NameError: name 'nvalid' is not defined
[2023-01-26T17:43:35.451+0000] {processor.py:755} WARNING - No viable dags retrieved from /opt/airflow/dags/etlcommands.py
[2023-01-26T17:43:35.479+0000] {processor.py:175} INFO - Processing /opt/airflow/dags/etlcommands.py took 0.297 seconds
[2023-01-26T17:44:06.390+0000] {processor.py:153} INFO - Started process (PID=4006) to work on /opt/airflow/dags/etlcommands.py
[2023-01-26T17:44:06.391+0000] {processor.py:743} INFO - Processing file /opt/airflow/dags/etlcommands.py for tasks to queue
[2023-01-26T17:44:06.391+0000] {logging_mixin.py:137} INFO - [2023-01-26T17:44:06.391+0000] {dagbag.py:538} INFO - Filling up the DagBag from /opt/airflow/dags/etlcommands.py
[2023-01-26T17:44:06.618+0000] {logging_mixin.py:137} INFO - [2023-01-26T17:44:06.617+0000] {dagbag.py:343} ERROR - Failed to import: /opt/airflow/dags/etlcommands.py
Traceback (most recent call last):
  File "/home/airflow/.local/lib/python3.7/site-packages/airflow/models/dagbag.py", line 339, in parse
    loader.exec_module(new_module)
  File "<frozen importlib._bootstrap_external>", line 728, in exec_module
  File "<frozen importlib._bootstrap>", line 219, in _call_with_frames_removed
  File "/opt/airflow/dags/etlcommands.py", line 46, in <module>
    capture_account_data >> is_valid >> [valid, nvalid]
NameError: name 'nvalid' is not defined
[2023-01-26T17:44:06.618+0000] {processor.py:755} WARNING - No viable dags retrieved from /opt/airflow/dags/etlcommands.py
[2023-01-26T17:44:06.641+0000] {processor.py:175} INFO - Processing /opt/airflow/dags/etlcommands.py took 0.256 seconds
[2023-01-26T17:44:37.008+0000] {processor.py:153} INFO - Started process (PID=4084) to work on /opt/airflow/dags/etlcommands.py
[2023-01-26T17:44:37.009+0000] {processor.py:743} INFO - Processing file /opt/airflow/dags/etlcommands.py for tasks to queue
[2023-01-26T17:44:37.010+0000] {logging_mixin.py:137} INFO - [2023-01-26T17:44:37.009+0000] {dagbag.py:538} INFO - Filling up the DagBag from /opt/airflow/dags/etlcommands.py
[2023-01-26T17:44:37.254+0000] {logging_mixin.py:137} INFO - [2023-01-26T17:44:37.253+0000] {dagbag.py:343} ERROR - Failed to import: /opt/airflow/dags/etlcommands.py
Traceback (most recent call last):
  File "/home/airflow/.local/lib/python3.7/site-packages/airflow/models/dagbag.py", line 339, in parse
    loader.exec_module(new_module)
  File "<frozen importlib._bootstrap_external>", line 728, in exec_module
  File "<frozen importlib._bootstrap>", line 219, in _call_with_frames_removed
  File "/opt/airflow/dags/etlcommands.py", line 46, in <module>
    capture_account_data >> is_valid >> [valid, nvalid]
NameError: name 'nvalid' is not defined
[2023-01-26T17:44:37.255+0000] {processor.py:755} WARNING - No viable dags retrieved from /opt/airflow/dags/etlcommands.py
[2023-01-26T17:44:37.278+0000] {processor.py:175} INFO - Processing /opt/airflow/dags/etlcommands.py took 0.274 seconds
[2023-01-26T17:45:07.355+0000] {processor.py:153} INFO - Started process (PID=4150) to work on /opt/airflow/dags/etlcommands.py
[2023-01-26T17:45:07.356+0000] {processor.py:743} INFO - Processing file /opt/airflow/dags/etlcommands.py for tasks to queue
[2023-01-26T17:45:07.356+0000] {logging_mixin.py:137} INFO - [2023-01-26T17:45:07.356+0000] {dagbag.py:538} INFO - Filling up the DagBag from /opt/airflow/dags/etlcommands.py
[2023-01-26T17:45:07.568+0000] {logging_mixin.py:137} INFO - [2023-01-26T17:45:07.567+0000] {dagbag.py:343} ERROR - Failed to import: /opt/airflow/dags/etlcommands.py
Traceback (most recent call last):
  File "/home/airflow/.local/lib/python3.7/site-packages/airflow/models/dagbag.py", line 339, in parse
    loader.exec_module(new_module)
  File "<frozen importlib._bootstrap_external>", line 728, in exec_module
  File "<frozen importlib._bootstrap>", line 219, in _call_with_frames_removed
  File "/opt/airflow/dags/etlcommands.py", line 46, in <module>
    capture_account_data >> is_valid >> [valid, nvalid]
NameError: name 'nvalid' is not defined
[2023-01-26T17:45:07.568+0000] {processor.py:755} WARNING - No viable dags retrieved from /opt/airflow/dags/etlcommands.py
[2023-01-26T17:45:07.590+0000] {processor.py:175} INFO - Processing /opt/airflow/dags/etlcommands.py took 0.239 seconds
[2023-01-26T17:45:37.639+0000] {processor.py:153} INFO - Started process (PID=4224) to work on /opt/airflow/dags/etlcommands.py
[2023-01-26T17:45:37.640+0000] {processor.py:743} INFO - Processing file /opt/airflow/dags/etlcommands.py for tasks to queue
[2023-01-26T17:45:37.641+0000] {logging_mixin.py:137} INFO - [2023-01-26T17:45:37.641+0000] {dagbag.py:538} INFO - Filling up the DagBag from /opt/airflow/dags/etlcommands.py
[2023-01-26T17:45:37.912+0000] {logging_mixin.py:137} INFO - [2023-01-26T17:45:37.911+0000] {dagbag.py:343} ERROR - Failed to import: /opt/airflow/dags/etlcommands.py
Traceback (most recent call last):
  File "/home/airflow/.local/lib/python3.7/site-packages/airflow/models/dagbag.py", line 339, in parse
    loader.exec_module(new_module)
  File "<frozen importlib._bootstrap_external>", line 728, in exec_module
  File "<frozen importlib._bootstrap>", line 219, in _call_with_frames_removed
  File "/opt/airflow/dags/etlcommands.py", line 46, in <module>
    capture_account_data >> is_valid >> [valid, nvalid]
NameError: name 'nvalid' is not defined
[2023-01-26T17:45:37.913+0000] {processor.py:755} WARNING - No viable dags retrieved from /opt/airflow/dags/etlcommands.py
[2023-01-26T17:45:37.937+0000] {processor.py:175} INFO - Processing /opt/airflow/dags/etlcommands.py took 0.302 seconds
[2023-01-26T17:46:08.801+0000] {processor.py:153} INFO - Started process (PID=4292) to work on /opt/airflow/dags/etlcommands.py
[2023-01-26T17:46:08.802+0000] {processor.py:743} INFO - Processing file /opt/airflow/dags/etlcommands.py for tasks to queue
[2023-01-26T17:46:08.803+0000] {logging_mixin.py:137} INFO - [2023-01-26T17:46:08.803+0000] {dagbag.py:538} INFO - Filling up the DagBag from /opt/airflow/dags/etlcommands.py
[2023-01-26T17:46:09.033+0000] {logging_mixin.py:137} INFO - [2023-01-26T17:46:09.033+0000] {dagbag.py:343} ERROR - Failed to import: /opt/airflow/dags/etlcommands.py
Traceback (most recent call last):
  File "/home/airflow/.local/lib/python3.7/site-packages/airflow/models/dagbag.py", line 339, in parse
    loader.exec_module(new_module)
  File "<frozen importlib._bootstrap_external>", line 728, in exec_module
  File "<frozen importlib._bootstrap>", line 219, in _call_with_frames_removed
  File "/opt/airflow/dags/etlcommands.py", line 46, in <module>
    capture_account_data >> is_valid >> [valid, nvalid]
NameError: name 'nvalid' is not defined
[2023-01-26T17:46:09.034+0000] {processor.py:755} WARNING - No viable dags retrieved from /opt/airflow/dags/etlcommands.py
[2023-01-26T17:46:09.058+0000] {processor.py:175} INFO - Processing /opt/airflow/dags/etlcommands.py took 0.260 seconds
[2023-01-26T17:46:39.524+0000] {processor.py:153} INFO - Started process (PID=4369) to work on /opt/airflow/dags/etlcommands.py
[2023-01-26T17:46:39.525+0000] {processor.py:743} INFO - Processing file /opt/airflow/dags/etlcommands.py for tasks to queue
[2023-01-26T17:46:39.526+0000] {logging_mixin.py:137} INFO - [2023-01-26T17:46:39.526+0000] {dagbag.py:538} INFO - Filling up the DagBag from /opt/airflow/dags/etlcommands.py
[2023-01-26T17:46:39.803+0000] {logging_mixin.py:137} INFO - [2023-01-26T17:46:39.802+0000] {dagbag.py:343} ERROR - Failed to import: /opt/airflow/dags/etlcommands.py
Traceback (most recent call last):
  File "/home/airflow/.local/lib/python3.7/site-packages/airflow/models/dagbag.py", line 339, in parse
    loader.exec_module(new_module)
  File "<frozen importlib._bootstrap_external>", line 728, in exec_module
  File "<frozen importlib._bootstrap>", line 219, in _call_with_frames_removed
  File "/opt/airflow/dags/etlcommands.py", line 46, in <module>
    capture_account_data >> is_valid >> [valid, nvalid]
NameError: name 'nvalid' is not defined
[2023-01-26T17:46:39.804+0000] {processor.py:755} WARNING - No viable dags retrieved from /opt/airflow/dags/etlcommands.py
[2023-01-26T17:46:39.835+0000] {processor.py:175} INFO - Processing /opt/airflow/dags/etlcommands.py took 0.316 seconds
[2023-01-26T17:47:10.154+0000] {processor.py:153} INFO - Started process (PID=4435) to work on /opt/airflow/dags/etlcommands.py
[2023-01-26T17:47:10.156+0000] {processor.py:743} INFO - Processing file /opt/airflow/dags/etlcommands.py for tasks to queue
[2023-01-26T17:47:10.157+0000] {logging_mixin.py:137} INFO - [2023-01-26T17:47:10.156+0000] {dagbag.py:538} INFO - Filling up the DagBag from /opt/airflow/dags/etlcommands.py
[2023-01-26T17:47:10.487+0000] {logging_mixin.py:137} INFO - [2023-01-26T17:47:10.486+0000] {dagbag.py:343} ERROR - Failed to import: /opt/airflow/dags/etlcommands.py
Traceback (most recent call last):
  File "/home/airflow/.local/lib/python3.7/site-packages/airflow/models/dagbag.py", line 339, in parse
    loader.exec_module(new_module)
  File "<frozen importlib._bootstrap_external>", line 728, in exec_module
  File "<frozen importlib._bootstrap>", line 219, in _call_with_frames_removed
  File "/opt/airflow/dags/etlcommands.py", line 46, in <module>
    capture_account_data >> is_valid >> [valid, nvalid]
NameError: name 'nvalid' is not defined
[2023-01-26T17:47:10.487+0000] {processor.py:755} WARNING - No viable dags retrieved from /opt/airflow/dags/etlcommands.py
[2023-01-26T17:47:10.516+0000] {processor.py:175} INFO - Processing /opt/airflow/dags/etlcommands.py took 0.366 seconds
[2023-01-26T17:47:40.960+0000] {processor.py:153} INFO - Started process (PID=4512) to work on /opt/airflow/dags/etlcommands.py
[2023-01-26T17:47:40.961+0000] {processor.py:743} INFO - Processing file /opt/airflow/dags/etlcommands.py for tasks to queue
[2023-01-26T17:47:40.961+0000] {logging_mixin.py:137} INFO - [2023-01-26T17:47:40.961+0000] {dagbag.py:538} INFO - Filling up the DagBag from /opt/airflow/dags/etlcommands.py
[2023-01-26T17:47:41.199+0000] {logging_mixin.py:137} INFO - [2023-01-26T17:47:41.198+0000] {dagbag.py:343} ERROR - Failed to import: /opt/airflow/dags/etlcommands.py
Traceback (most recent call last):
  File "/home/airflow/.local/lib/python3.7/site-packages/airflow/models/dagbag.py", line 339, in parse
    loader.exec_module(new_module)
  File "<frozen importlib._bootstrap_external>", line 728, in exec_module
  File "<frozen importlib._bootstrap>", line 219, in _call_with_frames_removed
  File "/opt/airflow/dags/etlcommands.py", line 46, in <module>
    capture_account_data >> is_valid >> [valid, nvalid]
NameError: name 'nvalid' is not defined
[2023-01-26T17:47:41.199+0000] {processor.py:755} WARNING - No viable dags retrieved from /opt/airflow/dags/etlcommands.py
[2023-01-26T17:47:41.227+0000] {processor.py:175} INFO - Processing /opt/airflow/dags/etlcommands.py took 0.270 seconds
[2023-01-26T17:48:11.430+0000] {processor.py:153} INFO - Started process (PID=4578) to work on /opt/airflow/dags/etlcommands.py
[2023-01-26T17:48:11.431+0000] {processor.py:743} INFO - Processing file /opt/airflow/dags/etlcommands.py for tasks to queue
[2023-01-26T17:48:11.432+0000] {logging_mixin.py:137} INFO - [2023-01-26T17:48:11.432+0000] {dagbag.py:538} INFO - Filling up the DagBag from /opt/airflow/dags/etlcommands.py
[2023-01-26T17:48:11.676+0000] {logging_mixin.py:137} INFO - [2023-01-26T17:48:11.675+0000] {dagbag.py:343} ERROR - Failed to import: /opt/airflow/dags/etlcommands.py
Traceback (most recent call last):
  File "/home/airflow/.local/lib/python3.7/site-packages/airflow/models/dagbag.py", line 339, in parse
    loader.exec_module(new_module)
  File "<frozen importlib._bootstrap_external>", line 728, in exec_module
  File "<frozen importlib._bootstrap>", line 219, in _call_with_frames_removed
  File "/opt/airflow/dags/etlcommands.py", line 46, in <module>
    capture_account_data >> is_valid >> [valid, nvalid]
NameError: name 'nvalid' is not defined
[2023-01-26T17:48:11.677+0000] {processor.py:755} WARNING - No viable dags retrieved from /opt/airflow/dags/etlcommands.py
[2023-01-26T17:48:11.699+0000] {processor.py:175} INFO - Processing /opt/airflow/dags/etlcommands.py took 0.272 seconds
[2023-01-26T17:48:42.226+0000] {processor.py:153} INFO - Started process (PID=4655) to work on /opt/airflow/dags/etlcommands.py
[2023-01-26T17:48:42.227+0000] {processor.py:743} INFO - Processing file /opt/airflow/dags/etlcommands.py for tasks to queue
[2023-01-26T17:48:42.228+0000] {logging_mixin.py:137} INFO - [2023-01-26T17:48:42.228+0000] {dagbag.py:538} INFO - Filling up the DagBag from /opt/airflow/dags/etlcommands.py
[2023-01-26T17:48:42.467+0000] {logging_mixin.py:137} INFO - [2023-01-26T17:48:42.466+0000] {dagbag.py:343} ERROR - Failed to import: /opt/airflow/dags/etlcommands.py
Traceback (most recent call last):
  File "/home/airflow/.local/lib/python3.7/site-packages/airflow/models/dagbag.py", line 339, in parse
    loader.exec_module(new_module)
  File "<frozen importlib._bootstrap_external>", line 728, in exec_module
  File "<frozen importlib._bootstrap>", line 219, in _call_with_frames_removed
  File "/opt/airflow/dags/etlcommands.py", line 46, in <module>
    capture_account_data >> is_valid >> [valid, nvalid]
NameError: name 'nvalid' is not defined
[2023-01-26T17:48:42.467+0000] {processor.py:755} WARNING - No viable dags retrieved from /opt/airflow/dags/etlcommands.py
[2023-01-26T17:48:42.492+0000] {processor.py:175} INFO - Processing /opt/airflow/dags/etlcommands.py took 0.269 seconds
[2023-01-26T17:49:12.856+0000] {processor.py:153} INFO - Started process (PID=4720) to work on /opt/airflow/dags/etlcommands.py
[2023-01-26T17:49:12.857+0000] {processor.py:743} INFO - Processing file /opt/airflow/dags/etlcommands.py for tasks to queue
[2023-01-26T17:49:12.858+0000] {logging_mixin.py:137} INFO - [2023-01-26T17:49:12.857+0000] {dagbag.py:538} INFO - Filling up the DagBag from /opt/airflow/dags/etlcommands.py
[2023-01-26T17:49:13.181+0000] {logging_mixin.py:137} INFO - [2023-01-26T17:49:13.180+0000] {dagbag.py:343} ERROR - Failed to import: /opt/airflow/dags/etlcommands.py
Traceback (most recent call last):
  File "/home/airflow/.local/lib/python3.7/site-packages/airflow/models/dagbag.py", line 339, in parse
    loader.exec_module(new_module)
  File "<frozen importlib._bootstrap_external>", line 728, in exec_module
  File "<frozen importlib._bootstrap>", line 219, in _call_with_frames_removed
  File "/opt/airflow/dags/etlcommands.py", line 46, in <module>
    capture_account_data >> is_valid >> [valid, nvalid]
NameError: name 'nvalid' is not defined
[2023-01-26T17:49:13.182+0000] {processor.py:755} WARNING - No viable dags retrieved from /opt/airflow/dags/etlcommands.py
[2023-01-26T17:49:13.212+0000] {processor.py:175} INFO - Processing /opt/airflow/dags/etlcommands.py took 0.360 seconds
[2023-01-26T17:49:44.177+0000] {processor.py:153} INFO - Started process (PID=4799) to work on /opt/airflow/dags/etlcommands.py
[2023-01-26T17:49:44.178+0000] {processor.py:743} INFO - Processing file /opt/airflow/dags/etlcommands.py for tasks to queue
[2023-01-26T17:49:44.179+0000] {logging_mixin.py:137} INFO - [2023-01-26T17:49:44.179+0000] {dagbag.py:538} INFO - Filling up the DagBag from /opt/airflow/dags/etlcommands.py
[2023-01-26T17:49:44.465+0000] {logging_mixin.py:137} INFO - [2023-01-26T17:49:44.464+0000] {dagbag.py:343} ERROR - Failed to import: /opt/airflow/dags/etlcommands.py
Traceback (most recent call last):
  File "/home/airflow/.local/lib/python3.7/site-packages/airflow/models/dagbag.py", line 339, in parse
    loader.exec_module(new_module)
  File "<frozen importlib._bootstrap_external>", line 728, in exec_module
  File "<frozen importlib._bootstrap>", line 219, in _call_with_frames_removed
  File "/opt/airflow/dags/etlcommands.py", line 46, in <module>
    capture_account_data >> is_valid >> [valid, nvalid]
NameError: name 'nvalid' is not defined
[2023-01-26T17:49:44.466+0000] {processor.py:755} WARNING - No viable dags retrieved from /opt/airflow/dags/etlcommands.py
[2023-01-26T17:49:44.490+0000] {processor.py:175} INFO - Processing /opt/airflow/dags/etlcommands.py took 0.317 seconds
[2023-01-26T17:50:15.352+0000] {processor.py:153} INFO - Started process (PID=4864) to work on /opt/airflow/dags/etlcommands.py
[2023-01-26T17:50:15.353+0000] {processor.py:743} INFO - Processing file /opt/airflow/dags/etlcommands.py for tasks to queue
[2023-01-26T17:50:15.354+0000] {logging_mixin.py:137} INFO - [2023-01-26T17:50:15.354+0000] {dagbag.py:538} INFO - Filling up the DagBag from /opt/airflow/dags/etlcommands.py
[2023-01-26T17:50:15.635+0000] {logging_mixin.py:137} INFO - [2023-01-26T17:50:15.634+0000] {dagbag.py:343} ERROR - Failed to import: /opt/airflow/dags/etlcommands.py
Traceback (most recent call last):
  File "/home/airflow/.local/lib/python3.7/site-packages/airflow/models/dagbag.py", line 339, in parse
    loader.exec_module(new_module)
  File "<frozen importlib._bootstrap_external>", line 728, in exec_module
  File "<frozen importlib._bootstrap>", line 219, in _call_with_frames_removed
  File "/opt/airflow/dags/etlcommands.py", line 46, in <module>
    capture_account_data >> is_valid >> [valid, nvalid]
NameError: name 'nvalid' is not defined
[2023-01-26T17:50:15.636+0000] {processor.py:755} WARNING - No viable dags retrieved from /opt/airflow/dags/etlcommands.py
[2023-01-26T17:50:15.668+0000] {processor.py:175} INFO - Processing /opt/airflow/dags/etlcommands.py took 0.320 seconds
[2023-01-26T17:50:45.820+0000] {processor.py:153} INFO - Started process (PID=4944) to work on /opt/airflow/dags/etlcommands.py
[2023-01-26T17:50:45.820+0000] {processor.py:743} INFO - Processing file /opt/airflow/dags/etlcommands.py for tasks to queue
[2023-01-26T17:50:45.821+0000] {logging_mixin.py:137} INFO - [2023-01-26T17:50:45.821+0000] {dagbag.py:538} INFO - Filling up the DagBag from /opt/airflow/dags/etlcommands.py
[2023-01-26T17:50:46.037+0000] {logging_mixin.py:137} INFO - [2023-01-26T17:50:46.036+0000] {dagbag.py:343} ERROR - Failed to import: /opt/airflow/dags/etlcommands.py
Traceback (most recent call last):
  File "/home/airflow/.local/lib/python3.7/site-packages/airflow/models/dagbag.py", line 339, in parse
    loader.exec_module(new_module)
  File "<frozen importlib._bootstrap_external>", line 728, in exec_module
  File "<frozen importlib._bootstrap>", line 219, in _call_with_frames_removed
  File "/opt/airflow/dags/etlcommands.py", line 46, in <module>
    capture_account_data >> is_valid >> [valid, nvalid]
NameError: name 'nvalid' is not defined
[2023-01-26T17:50:46.037+0000] {processor.py:755} WARNING - No viable dags retrieved from /opt/airflow/dags/etlcommands.py
[2023-01-26T17:50:46.063+0000] {processor.py:175} INFO - Processing /opt/airflow/dags/etlcommands.py took 0.246 seconds
